[I 2023-05-23 12:51:57.852 ServerApp] Package jupyterlab took 0.0000s to import
[I 2023-05-23 12:51:57.877 ServerApp] Package jupyter_lsp took 0.0251s to import
[W 2023-05-23 12:51:57.877 ServerApp] A `_jupyter_server_extension_points` function was not found in jupyter_lsp. Instead, a `_jupyter_server_extension_paths` function was found and will be used for now. This function name will be deprecated in future releases of Jupyter Server.
[I 2023-05-23 12:51:57.889 ServerApp] Package jupyter_server_terminals took 0.0115s to import
[I 2023-05-23 12:51:57.889 ServerApp] Package notebook_shim took 0.0000s to import
[W 2023-05-23 12:51:57.890 ServerApp] A `_jupyter_server_extension_points` function was not found in notebook_shim. Instead, a `_jupyter_server_extension_paths` function was found and will be used for now. This function name will be deprecated in future releases of Jupyter Server.
[I 2023-05-23 12:51:57.890 ServerApp] jupyter_lsp | extension was successfully linked.
[I 2023-05-23 12:51:57.894 ServerApp] jupyter_server_terminals | extension was successfully linked.
[I 2023-05-23 12:51:57.898 ServerApp] jupyterlab | extension was successfully linked.
[I 2023-05-23 12:51:58.260 ServerApp] notebook_shim | extension was successfully linked.
[I 2023-05-23 12:51:58.290 ServerApp] notebook_shim | extension was successfully loaded.
[I 2023-05-23 12:51:58.318 ServerApp] jupyter_lsp | extension was successfully loaded.
[I 2023-05-23 12:51:58.320 ServerApp] jupyter_server_terminals | extension was successfully loaded.
[I 2023-05-23 12:51:58.320 LabApp] JupyterLab extension loaded from /usr/local/lib/python3.11/site-packages/jupyterlab
[I 2023-05-23 12:51:58.320 LabApp] JupyterLab application directory is /usr/local/share/jupyter/lab
[I 2023-05-23 12:51:58.321 LabApp] Extension Manager is 'pypi'.
[I 2023-05-23 12:51:58.322 ServerApp] jupyterlab | extension was successfully loaded.
[I 2023-05-23 12:51:58.323 ServerApp] Serving notebooks from local directory: /Users/zhaoji/Develop/projects/pythonProgram
[I 2023-05-23 12:51:58.323 ServerApp] Jupyter Server 2.5.0 is running at:
[I 2023-05-23 12:51:58.323 ServerApp] http://localhost:8888/lab?token=01a6a969d71554f3edb3497a4bf77ff3ca73b76337ac726d
[I 2023-05-23 12:51:58.323 ServerApp]     http://127.0.0.1:8888/lab?token=01a6a969d71554f3edb3497a4bf77ff3ca73b76337ac726d
[I 2023-05-23 12:51:58.323 ServerApp] Use Control-C to stop this server and shut down all kernels (twice to skip confirmation).
[C 2023-05-23 12:51:58.331 ServerApp] 
    
    To access the server, open this file in a browser:
        file:///Users/zhaoji/Library/Jupyter/runtime/jpserver-47293-open.html
    Or copy and paste one of these URLs:
        http://localhost:8888/lab?token=01a6a969d71554f3edb3497a4bf77ff3ca73b76337ac726d
        http://127.0.0.1:8888/lab?token=01a6a969d71554f3edb3497a4bf77ff3ca73b76337ac726d
[I 2023-05-23 12:51:58.349 ServerApp] Skipped non-installed server(s): bash-language-server, dockerfile-language-server-nodejs, javascript-typescript-langserver, jedi-language-server, julia-language-server, pyright, python-language-server, python-lsp-server, r-languageserver, sql-language-server, texlab, typescript-language-server, unified-language-server, vscode-css-languageserver-bin, vscode-html-languageserver-bin, vscode-json-languageserver-bin, yaml-language-server
0.00s - Debugger warning: It seems that frozen modules are being used, which may
0.00s - make the debugger miss breakpoints. Please pass -Xfrozen_modules=off
0.00s - to python to disable frozen modules.
0.00s - Note: Debugging will proceed. Set PYDEVD_DISABLE_FILE_VALIDATION=1 to disable this validation.
[W 2023-05-23 12:52:01.356 LabApp] Could not determine jupyterlab build status without nodejs
[W 2023-05-23 12:52:02.938 ServerApp] 404 GET /api/kernels/972be443-61c2-4ade-8186-3ca3b9aa31fa?1684817522935 (::1): Kernel does not exist: 972be443-61c2-4ade-8186-3ca3b9aa31fa
[W 2023-05-23 12:52:02.938 ServerApp] wrote error: 'Kernel does not exist: 972be443-61c2-4ade-8186-3ca3b9aa31fa'
    Traceback (most recent call last):
      File "/usr/local/lib/python3.11/site-packages/tornado/web.py", line 1786, in _execute
        result = await result
                 ^^^^^^^^^^^^
      File "/usr/local/lib/python3.11/site-packages/jupyter_server/services/kernels/handlers.py", line 72, in get
        model = await ensure_async(km.kernel_model(kernel_id))
                                   ^^^^^^^^^^^^^^^^^^^^^^^^^^
      File "/usr/local/lib/python3.11/site-packages/jupyter_server/services/kernels/kernelmanager.py", line 496, in kernel_model
        self._check_kernel_id(kernel_id)
      File "/usr/local/lib/python3.11/site-packages/jupyter_server/services/kernels/kernelmanager.py", line 527, in _check_kernel_id
        raise web.HTTPError(404, "Kernel does not exist: %s" % kernel_id)
    tornado.web.HTTPError: HTTP 404: Not Found (Kernel does not exist: 972be443-61c2-4ade-8186-3ca3b9aa31fa)
[W 2023-05-23 12:52:02.945 ServerApp] 404 GET /api/kernels/972be443-61c2-4ade-8186-3ca3b9aa31fa?1684817522935 (42442f52999c44fca217868bf36576d9@::1) 7.75ms referer=http://localhost:8888/lab/workspaces/auto-Z/tree/exception.ipynb
[W 2023-05-23 12:52:04.448 ServerApp] 404 GET /api/kernels/972be443-61c2-4ade-8186-3ca3b9aa31fa/channels?session_id=be6b67ec-4935-4491-ad7a-26e7cac5cc86 (::1): Kernel does not exist: 972be443-61c2-4ade-8186-3ca3b9aa31fa
[W 2023-05-23 12:52:04.472 ServerApp] 404 GET /api/kernels/972be443-61c2-4ade-8186-3ca3b9aa31fa/channels?session_id=be6b67ec-4935-4491-ad7a-26e7cac5cc86 (42442f52999c44fca217868bf36576d9@::1) 24.22ms referer=None
[W 2023-05-23 12:52:04.474 ServerApp] 404 GET /api/kernels/972be443-61c2-4ade-8186-3ca3b9aa31fa?1684817524472 (::1): Kernel does not exist: 972be443-61c2-4ade-8186-3ca3b9aa31fa
[W 2023-05-23 12:52:04.474 ServerApp] wrote error: 'Kernel does not exist: 972be443-61c2-4ade-8186-3ca3b9aa31fa'
    Traceback (most recent call last):
      File "/usr/local/lib/python3.11/site-packages/tornado/web.py", line 1786, in _execute
        result = await result
                 ^^^^^^^^^^^^
      File "/usr/local/lib/python3.11/site-packages/jupyter_server/services/kernels/handlers.py", line 72, in get
        model = await ensure_async(km.kernel_model(kernel_id))
                                   ^^^^^^^^^^^^^^^^^^^^^^^^^^
      File "/usr/local/lib/python3.11/site-packages/jupyter_server/services/kernels/kernelmanager.py", line 496, in kernel_model
        self._check_kernel_id(kernel_id)
      File "/usr/local/lib/python3.11/site-packages/jupyter_server/services/kernels/kernelmanager.py", line 527, in _check_kernel_id
        raise web.HTTPError(404, "Kernel does not exist: %s" % kernel_id)
    tornado.web.HTTPError: HTTP 404: Not Found (Kernel does not exist: 972be443-61c2-4ade-8186-3ca3b9aa31fa)
[W 2023-05-23 12:52:04.475 ServerApp] 404 GET /api/kernels/972be443-61c2-4ade-8186-3ca3b9aa31fa?1684817524472 (42442f52999c44fca217868bf36576d9@::1) 1.27ms referer=http://localhost:8888/lab/workspaces/auto-Z/tree/exception.ipynb
[W 2023-05-23 12:52:05.448 ServerApp] 404 GET /api/kernels/972be443-61c2-4ade-8186-3ca3b9aa31fa/channels?session_id=be6b67ec-4935-4491-ad7a-26e7cac5cc86 (::1): Kernel does not exist: 972be443-61c2-4ade-8186-3ca3b9aa31fa
[W 2023-05-23 12:52:05.449 ServerApp] 404 GET /api/kernels/972be443-61c2-4ade-8186-3ca3b9aa31fa/channels?session_id=be6b67ec-4935-4491-ad7a-26e7cac5cc86 (42442f52999c44fca217868bf36576d9@::1) 1.60ms referer=None
[W 2023-05-23 12:52:05.451 ServerApp] 404 GET /api/kernels/972be443-61c2-4ade-8186-3ca3b9aa31fa?1684817525449 (::1): Kernel does not exist: 972be443-61c2-4ade-8186-3ca3b9aa31fa
[W 2023-05-23 12:52:05.451 ServerApp] wrote error: 'Kernel does not exist: 972be443-61c2-4ade-8186-3ca3b9aa31fa'
    Traceback (most recent call last):
      File "/usr/local/lib/python3.11/site-packages/tornado/web.py", line 1786, in _execute
        result = await result
                 ^^^^^^^^^^^^
      File "/usr/local/lib/python3.11/site-packages/jupyter_server/services/kernels/handlers.py", line 72, in get
        model = await ensure_async(km.kernel_model(kernel_id))
                                   ^^^^^^^^^^^^^^^^^^^^^^^^^^
      File "/usr/local/lib/python3.11/site-packages/jupyter_server/services/kernels/kernelmanager.py", line 496, in kernel_model
        self._check_kernel_id(kernel_id)
      File "/usr/local/lib/python3.11/site-packages/jupyter_server/services/kernels/kernelmanager.py", line 527, in _check_kernel_id
        raise web.HTTPError(404, "Kernel does not exist: %s" % kernel_id)
    tornado.web.HTTPError: HTTP 404: Not Found (Kernel does not exist: 972be443-61c2-4ade-8186-3ca3b9aa31fa)
[W 2023-05-23 12:52:05.452 ServerApp] 404 GET /api/kernels/972be443-61c2-4ade-8186-3ca3b9aa31fa?1684817525449 (42442f52999c44fca217868bf36576d9@::1) 1.28ms referer=http://localhost:8888/lab/workspaces/auto-Z/tree/exception.ipynb
[W 2023-05-23 12:52:08.448 ServerApp] 404 GET /api/kernels/972be443-61c2-4ade-8186-3ca3b9aa31fa/channels?session_id=be6b67ec-4935-4491-ad7a-26e7cac5cc86 (::1): Kernel does not exist: 972be443-61c2-4ade-8186-3ca3b9aa31fa
[W 2023-05-23 12:52:08.449 ServerApp] 404 GET /api/kernels/972be443-61c2-4ade-8186-3ca3b9aa31fa/channels?session_id=be6b67ec-4935-4491-ad7a-26e7cac5cc86 (42442f52999c44fca217868bf36576d9@::1) 1.43ms referer=None
[W 2023-05-23 12:52:08.451 ServerApp] 404 GET /api/kernels/972be443-61c2-4ade-8186-3ca3b9aa31fa?1684817528449 (::1): Kernel does not exist: 972be443-61c2-4ade-8186-3ca3b9aa31fa
[W 2023-05-23 12:52:08.451 ServerApp] wrote error: 'Kernel does not exist: 972be443-61c2-4ade-8186-3ca3b9aa31fa'
    Traceback (most recent call last):
      File "/usr/local/lib/python3.11/site-packages/tornado/web.py", line 1786, in _execute
        result = await result
                 ^^^^^^^^^^^^
      File "/usr/local/lib/python3.11/site-packages/jupyter_server/services/kernels/handlers.py", line 72, in get
        model = await ensure_async(km.kernel_model(kernel_id))
                                   ^^^^^^^^^^^^^^^^^^^^^^^^^^
      File "/usr/local/lib/python3.11/site-packages/jupyter_server/services/kernels/kernelmanager.py", line 496, in kernel_model
        self._check_kernel_id(kernel_id)
      File "/usr/local/lib/python3.11/site-packages/jupyter_server/services/kernels/kernelmanager.py", line 527, in _check_kernel_id
        raise web.HTTPError(404, "Kernel does not exist: %s" % kernel_id)
    tornado.web.HTTPError: HTTP 404: Not Found (Kernel does not exist: 972be443-61c2-4ade-8186-3ca3b9aa31fa)
[W 2023-05-23 12:52:08.452 ServerApp] 404 GET /api/kernels/972be443-61c2-4ade-8186-3ca3b9aa31fa?1684817528449 (42442f52999c44fca217868bf36576d9@::1) 1.22ms referer=http://localhost:8888/lab/workspaces/auto-Z/tree/exception.ipynb
[W 2023-05-23 12:52:11.596 ServerApp] 404 GET /api/kernels/972be443-61c2-4ade-8186-3ca3b9aa31fa/channels?session_id=be6b67ec-4935-4491-ad7a-26e7cac5cc86 (::1): Kernel does not exist: 972be443-61c2-4ade-8186-3ca3b9aa31fa
[W 2023-05-23 12:52:11.597 ServerApp] 404 GET /api/kernels/972be443-61c2-4ade-8186-3ca3b9aa31fa/channels?session_id=be6b67ec-4935-4491-ad7a-26e7cac5cc86 (42442f52999c44fca217868bf36576d9@::1) 1.24ms referer=None
[W 2023-05-23 12:52:11.599 ServerApp] 404 GET /api/kernels/972be443-61c2-4ade-8186-3ca3b9aa31fa?1684817531597 (::1): Kernel does not exist: 972be443-61c2-4ade-8186-3ca3b9aa31fa
[W 2023-05-23 12:52:11.599 ServerApp] wrote error: 'Kernel does not exist: 972be443-61c2-4ade-8186-3ca3b9aa31fa'
    Traceback (most recent call last):
      File "/usr/local/lib/python3.11/site-packages/tornado/web.py", line 1786, in _execute
        result = await result
                 ^^^^^^^^^^^^
      File "/usr/local/lib/python3.11/site-packages/jupyter_server/services/kernels/handlers.py", line 72, in get
        model = await ensure_async(km.kernel_model(kernel_id))
                                   ^^^^^^^^^^^^^^^^^^^^^^^^^^
      File "/usr/local/lib/python3.11/site-packages/jupyter_server/services/kernels/kernelmanager.py", line 496, in kernel_model
        self._check_kernel_id(kernel_id)
      File "/usr/local/lib/python3.11/site-packages/jupyter_server/services/kernels/kernelmanager.py", line 527, in _check_kernel_id
        raise web.HTTPError(404, "Kernel does not exist: %s" % kernel_id)
    tornado.web.HTTPError: HTTP 404: Not Found (Kernel does not exist: 972be443-61c2-4ade-8186-3ca3b9aa31fa)
[W 2023-05-23 12:52:11.600 ServerApp] 404 GET /api/kernels/972be443-61c2-4ade-8186-3ca3b9aa31fa?1684817531597 (42442f52999c44fca217868bf36576d9@::1) 1.11ms referer=http://localhost:8888/lab/workspaces/auto-Z/tree/exception.ipynb
[W 2023-05-23 12:52:17.737 ServerApp] 404 GET /api/kernels/972be443-61c2-4ade-8186-3ca3b9aa31fa/channels?session_id=be6b67ec-4935-4491-ad7a-26e7cac5cc86 (::1): Kernel does not exist: 972be443-61c2-4ade-8186-3ca3b9aa31fa
[W 2023-05-23 12:52:17.738 ServerApp] 404 GET /api/kernels/972be443-61c2-4ade-8186-3ca3b9aa31fa/channels?session_id=be6b67ec-4935-4491-ad7a-26e7cac5cc86 (42442f52999c44fca217868bf36576d9@::1) 1.75ms referer=None
[W 2023-05-23 12:52:17.741 ServerApp] 404 GET /api/kernels/972be443-61c2-4ade-8186-3ca3b9aa31fa?1684817537739 (::1): Kernel does not exist: 972be443-61c2-4ade-8186-3ca3b9aa31fa
[W 2023-05-23 12:52:17.741 ServerApp] wrote error: 'Kernel does not exist: 972be443-61c2-4ade-8186-3ca3b9aa31fa'
    Traceback (most recent call last):
      File "/usr/local/lib/python3.11/site-packages/tornado/web.py", line 1786, in _execute
        result = await result
                 ^^^^^^^^^^^^
      File "/usr/local/lib/python3.11/site-packages/jupyter_server/services/kernels/handlers.py", line 72, in get
        model = await ensure_async(km.kernel_model(kernel_id))
                                   ^^^^^^^^^^^^^^^^^^^^^^^^^^
      File "/usr/local/lib/python3.11/site-packages/jupyter_server/services/kernels/kernelmanager.py", line 496, in kernel_model
        self._check_kernel_id(kernel_id)
      File "/usr/local/lib/python3.11/site-packages/jupyter_server/services/kernels/kernelmanager.py", line 527, in _check_kernel_id
        raise web.HTTPError(404, "Kernel does not exist: %s" % kernel_id)
    tornado.web.HTTPError: HTTP 404: Not Found (Kernel does not exist: 972be443-61c2-4ade-8186-3ca3b9aa31fa)
[W 2023-05-23 12:52:17.742 ServerApp] 404 GET /api/kernels/972be443-61c2-4ade-8186-3ca3b9aa31fa?1684817537739 (42442f52999c44fca217868bf36576d9@::1) 1.20ms referer=http://localhost:8888/lab/workspaces/auto-Z/tree/exception.ipynb
[W 2023-05-23 12:52:20.672 ServerApp] 404 GET /api/kernels/e632738a-a9b7-4c57-a212-1e2a49e4e75b?1684817540669 (::1): Kernel does not exist: e632738a-a9b7-4c57-a212-1e2a49e4e75b
[W 2023-05-23 12:52:20.673 ServerApp] wrote error: 'Kernel does not exist: e632738a-a9b7-4c57-a212-1e2a49e4e75b'
    Traceback (most recent call last):
      File "/usr/local/lib/python3.11/site-packages/tornado/web.py", line 1786, in _execute
        result = await result
                 ^^^^^^^^^^^^
      File "/usr/local/lib/python3.11/site-packages/jupyter_server/services/kernels/handlers.py", line 72, in get
        model = await ensure_async(km.kernel_model(kernel_id))
                                   ^^^^^^^^^^^^^^^^^^^^^^^^^^
      File "/usr/local/lib/python3.11/site-packages/jupyter_server/services/kernels/kernelmanager.py", line 496, in kernel_model
        self._check_kernel_id(kernel_id)
      File "/usr/local/lib/python3.11/site-packages/jupyter_server/services/kernels/kernelmanager.py", line 527, in _check_kernel_id
        raise web.HTTPError(404, "Kernel does not exist: %s" % kernel_id)
    tornado.web.HTTPError: HTTP 404: Not Found (Kernel does not exist: e632738a-a9b7-4c57-a212-1e2a49e4e75b)
[W 2023-05-23 12:52:20.673 ServerApp] 404 GET /api/kernels/e632738a-a9b7-4c57-a212-1e2a49e4e75b?1684817540669 (42442f52999c44fca217868bf36576d9@::1) 1.63ms referer=http://localhost:8888/lab/workspaces/auto-6/tree/complexData.ipynb
[W 2023-05-23 12:52:21.762 ServerApp] 404 GET /api/kernels/e632738a-a9b7-4c57-a212-1e2a49e4e75b/channels?session_id=15e6b46a-2205-43ed-bafa-0217a030c3d0 (::1): Kernel does not exist: e632738a-a9b7-4c57-a212-1e2a49e4e75b
[W 2023-05-23 12:52:21.763 ServerApp] 404 GET /api/kernels/e632738a-a9b7-4c57-a212-1e2a49e4e75b/channels?session_id=15e6b46a-2205-43ed-bafa-0217a030c3d0 (42442f52999c44fca217868bf36576d9@::1) 1.59ms referer=None
[W 2023-05-23 12:52:21.765 ServerApp] 404 GET /api/kernels/e632738a-a9b7-4c57-a212-1e2a49e4e75b?1684817541763 (::1): Kernel does not exist: e632738a-a9b7-4c57-a212-1e2a49e4e75b
[W 2023-05-23 12:52:21.765 ServerApp] wrote error: 'Kernel does not exist: e632738a-a9b7-4c57-a212-1e2a49e4e75b'
    Traceback (most recent call last):
      File "/usr/local/lib/python3.11/site-packages/tornado/web.py", line 1786, in _execute
        result = await result
                 ^^^^^^^^^^^^
      File "/usr/local/lib/python3.11/site-packages/jupyter_server/services/kernels/handlers.py", line 72, in get
        model = await ensure_async(km.kernel_model(kernel_id))
                                   ^^^^^^^^^^^^^^^^^^^^^^^^^^
      File "/usr/local/lib/python3.11/site-packages/jupyter_server/services/kernels/kernelmanager.py", line 496, in kernel_model
        self._check_kernel_id(kernel_id)
      File "/usr/local/lib/python3.11/site-packages/jupyter_server/services/kernels/kernelmanager.py", line 527, in _check_kernel_id
        raise web.HTTPError(404, "Kernel does not exist: %s" % kernel_id)
    tornado.web.HTTPError: HTTP 404: Not Found (Kernel does not exist: e632738a-a9b7-4c57-a212-1e2a49e4e75b)
[W 2023-05-23 12:52:21.766 ServerApp] 404 GET /api/kernels/e632738a-a9b7-4c57-a212-1e2a49e4e75b?1684817541763 (42442f52999c44fca217868bf36576d9@::1) 1.23ms referer=http://localhost:8888/lab/workspaces/auto-6/tree/complexData.ipynb
[W 2023-05-23 12:52:22.447 ServerApp] 404 GET /api/kernels/e632738a-a9b7-4c57-a212-1e2a49e4e75b/channels?session_id=15e6b46a-2205-43ed-bafa-0217a030c3d0 (::1): Kernel does not exist: e632738a-a9b7-4c57-a212-1e2a49e4e75b
[W 2023-05-23 12:52:22.448 ServerApp] 404 GET /api/kernels/e632738a-a9b7-4c57-a212-1e2a49e4e75b/channels?session_id=15e6b46a-2205-43ed-bafa-0217a030c3d0 (42442f52999c44fca217868bf36576d9@::1) 0.93ms referer=None
[W 2023-05-23 12:52:22.450 ServerApp] 404 GET /api/kernels/e632738a-a9b7-4c57-a212-1e2a49e4e75b?1684817542448 (::1): Kernel does not exist: e632738a-a9b7-4c57-a212-1e2a49e4e75b
[W 2023-05-23 12:52:22.450 ServerApp] wrote error: 'Kernel does not exist: e632738a-a9b7-4c57-a212-1e2a49e4e75b'
    Traceback (most recent call last):
      File "/usr/local/lib/python3.11/site-packages/tornado/web.py", line 1786, in _execute
        result = await result
                 ^^^^^^^^^^^^
      File "/usr/local/lib/python3.11/site-packages/jupyter_server/services/kernels/handlers.py", line 72, in get
        model = await ensure_async(km.kernel_model(kernel_id))
                                   ^^^^^^^^^^^^^^^^^^^^^^^^^^
      File "/usr/local/lib/python3.11/site-packages/jupyter_server/services/kernels/kernelmanager.py", line 496, in kernel_model
        self._check_kernel_id(kernel_id)
      File "/usr/local/lib/python3.11/site-packages/jupyter_server/services/kernels/kernelmanager.py", line 527, in _check_kernel_id
        raise web.HTTPError(404, "Kernel does not exist: %s" % kernel_id)
    tornado.web.HTTPError: HTTP 404: Not Found (Kernel does not exist: e632738a-a9b7-4c57-a212-1e2a49e4e75b)
[W 2023-05-23 12:52:22.450 ServerApp] 404 GET /api/kernels/e632738a-a9b7-4c57-a212-1e2a49e4e75b?1684817542448 (42442f52999c44fca217868bf36576d9@::1) 0.81ms referer=http://localhost:8888/lab/workspaces/auto-6/tree/complexData.ipynb
[W 2023-05-23 12:52:29.457 ServerApp] 404 GET /api/kernels/e632738a-a9b7-4c57-a212-1e2a49e4e75b/channels?session_id=15e6b46a-2205-43ed-bafa-0217a030c3d0 (::1): Kernel does not exist: e632738a-a9b7-4c57-a212-1e2a49e4e75b
[W 2023-05-23 12:52:29.458 ServerApp] 404 GET /api/kernels/e632738a-a9b7-4c57-a212-1e2a49e4e75b/channels?session_id=15e6b46a-2205-43ed-bafa-0217a030c3d0 (42442f52999c44fca217868bf36576d9@::1) 1.27ms referer=None
[W 2023-05-23 12:52:29.460 ServerApp] 404 GET /api/kernels/e632738a-a9b7-4c57-a212-1e2a49e4e75b?1684817549458 (::1): Kernel does not exist: e632738a-a9b7-4c57-a212-1e2a49e4e75b
[W 2023-05-23 12:52:29.460 ServerApp] wrote error: 'Kernel does not exist: e632738a-a9b7-4c57-a212-1e2a49e4e75b'
    Traceback (most recent call last):
      File "/usr/local/lib/python3.11/site-packages/tornado/web.py", line 1786, in _execute
        result = await result
                 ^^^^^^^^^^^^
      File "/usr/local/lib/python3.11/site-packages/jupyter_server/services/kernels/handlers.py", line 72, in get
        model = await ensure_async(km.kernel_model(kernel_id))
                                   ^^^^^^^^^^^^^^^^^^^^^^^^^^
      File "/usr/local/lib/python3.11/site-packages/jupyter_server/services/kernels/kernelmanager.py", line 496, in kernel_model
        self._check_kernel_id(kernel_id)
      File "/usr/local/lib/python3.11/site-packages/jupyter_server/services/kernels/kernelmanager.py", line 527, in _check_kernel_id
        raise web.HTTPError(404, "Kernel does not exist: %s" % kernel_id)
    tornado.web.HTTPError: HTTP 404: Not Found (Kernel does not exist: e632738a-a9b7-4c57-a212-1e2a49e4e75b)
[W 2023-05-23 12:52:29.460 ServerApp] 404 GET /api/kernels/e632738a-a9b7-4c57-a212-1e2a49e4e75b?1684817549458 (42442f52999c44fca217868bf36576d9@::1) 1.16ms referer=http://localhost:8888/lab/workspaces/auto-6/tree/complexData.ipynb
[W 2023-05-23 12:52:35.326 ServerApp] 404 GET /api/kernels/e632738a-a9b7-4c57-a212-1e2a49e4e75b/channels?session_id=15e6b46a-2205-43ed-bafa-0217a030c3d0 (::1): Kernel does not exist: e632738a-a9b7-4c57-a212-1e2a49e4e75b
[W 2023-05-23 12:52:35.327 ServerApp] 404 GET /api/kernels/e632738a-a9b7-4c57-a212-1e2a49e4e75b/channels?session_id=15e6b46a-2205-43ed-bafa-0217a030c3d0 (42442f52999c44fca217868bf36576d9@::1) 1.16ms referer=None
[W 2023-05-23 12:52:35.329 ServerApp] 404 GET /api/kernels/e632738a-a9b7-4c57-a212-1e2a49e4e75b?1684817555327 (::1): Kernel does not exist: e632738a-a9b7-4c57-a212-1e2a49e4e75b
[W 2023-05-23 12:52:35.329 ServerApp] wrote error: 'Kernel does not exist: e632738a-a9b7-4c57-a212-1e2a49e4e75b'
    Traceback (most recent call last):
      File "/usr/local/lib/python3.11/site-packages/tornado/web.py", line 1786, in _execute
        result = await result
                 ^^^^^^^^^^^^
      File "/usr/local/lib/python3.11/site-packages/jupyter_server/services/kernels/handlers.py", line 72, in get
        model = await ensure_async(km.kernel_model(kernel_id))
                                   ^^^^^^^^^^^^^^^^^^^^^^^^^^
      File "/usr/local/lib/python3.11/site-packages/jupyter_server/services/kernels/kernelmanager.py", line 496, in kernel_model
        self._check_kernel_id(kernel_id)
      File "/usr/local/lib/python3.11/site-packages/jupyter_server/services/kernels/kernelmanager.py", line 527, in _check_kernel_id
        raise web.HTTPError(404, "Kernel does not exist: %s" % kernel_id)
    tornado.web.HTTPError: HTTP 404: Not Found (Kernel does not exist: e632738a-a9b7-4c57-a212-1e2a49e4e75b)
[W 2023-05-23 12:52:35.330 ServerApp] 404 GET /api/kernels/e632738a-a9b7-4c57-a212-1e2a49e4e75b?1684817555327 (42442f52999c44fca217868bf36576d9@::1) 1.07ms referer=http://localhost:8888/lab/workspaces/auto-6/tree/complexData.ipynb
[W 2023-05-23 12:52:41.464 ServerApp] 404 GET /api/kernels/e632738a-a9b7-4c57-a212-1e2a49e4e75b/channels?session_id=15e6b46a-2205-43ed-bafa-0217a030c3d0 (::1): Kernel does not exist: e632738a-a9b7-4c57-a212-1e2a49e4e75b
[W 2023-05-23 12:52:41.465 ServerApp] 404 GET /api/kernels/e632738a-a9b7-4c57-a212-1e2a49e4e75b/channels?session_id=15e6b46a-2205-43ed-bafa-0217a030c3d0 (42442f52999c44fca217868bf36576d9@::1) 1.30ms referer=None
[W 2023-05-23 12:52:41.467 ServerApp] 404 GET /api/kernels/e632738a-a9b7-4c57-a212-1e2a49e4e75b?1684817561465 (::1): Kernel does not exist: e632738a-a9b7-4c57-a212-1e2a49e4e75b
[W 2023-05-23 12:52:41.467 ServerApp] wrote error: 'Kernel does not exist: e632738a-a9b7-4c57-a212-1e2a49e4e75b'
    Traceback (most recent call last):
      File "/usr/local/lib/python3.11/site-packages/tornado/web.py", line 1786, in _execute
        result = await result
                 ^^^^^^^^^^^^
      File "/usr/local/lib/python3.11/site-packages/jupyter_server/services/kernels/handlers.py", line 72, in get
        model = await ensure_async(km.kernel_model(kernel_id))
                                   ^^^^^^^^^^^^^^^^^^^^^^^^^^
      File "/usr/local/lib/python3.11/site-packages/jupyter_server/services/kernels/kernelmanager.py", line 496, in kernel_model
        self._check_kernel_id(kernel_id)
      File "/usr/local/lib/python3.11/site-packages/jupyter_server/services/kernels/kernelmanager.py", line 527, in _check_kernel_id
        raise web.HTTPError(404, "Kernel does not exist: %s" % kernel_id)
    tornado.web.HTTPError: HTTP 404: Not Found (Kernel does not exist: e632738a-a9b7-4c57-a212-1e2a49e4e75b)
[W 2023-05-23 12:52:41.468 ServerApp] 404 GET /api/kernels/e632738a-a9b7-4c57-a212-1e2a49e4e75b?1684817561465 (42442f52999c44fca217868bf36576d9@::1) 1.21ms referer=http://localhost:8888/lab/workspaces/auto-6/tree/complexData.ipynb
[W 2023-05-23 12:52:43.465 ServerApp] 404 GET /api/kernels/972be443-61c2-4ade-8186-3ca3b9aa31fa/channels?session_id=be6b67ec-4935-4491-ad7a-26e7cac5cc86 (::1): Kernel does not exist: 972be443-61c2-4ade-8186-3ca3b9aa31fa
[W 2023-05-23 12:52:43.465 ServerApp] 404 GET /api/kernels/972be443-61c2-4ade-8186-3ca3b9aa31fa/channels?session_id=be6b67ec-4935-4491-ad7a-26e7cac5cc86 (42442f52999c44fca217868bf36576d9@::1) 1.24ms referer=None
[W 2023-05-23 12:52:43.468 ServerApp] 404 GET /api/kernels/972be443-61c2-4ade-8186-3ca3b9aa31fa?1684817563466 (::1): Kernel does not exist: 972be443-61c2-4ade-8186-3ca3b9aa31fa
[W 2023-05-23 12:52:43.468 ServerApp] wrote error: 'Kernel does not exist: 972be443-61c2-4ade-8186-3ca3b9aa31fa'
    Traceback (most recent call last):
      File "/usr/local/lib/python3.11/site-packages/tornado/web.py", line 1786, in _execute
        result = await result
                 ^^^^^^^^^^^^
      File "/usr/local/lib/python3.11/site-packages/jupyter_server/services/kernels/handlers.py", line 72, in get
        model = await ensure_async(km.kernel_model(kernel_id))
                                   ^^^^^^^^^^^^^^^^^^^^^^^^^^
      File "/usr/local/lib/python3.11/site-packages/jupyter_server/services/kernels/kernelmanager.py", line 496, in kernel_model
        self._check_kernel_id(kernel_id)
      File "/usr/local/lib/python3.11/site-packages/jupyter_server/services/kernels/kernelmanager.py", line 527, in _check_kernel_id
        raise web.HTTPError(404, "Kernel does not exist: %s" % kernel_id)
    tornado.web.HTTPError: HTTP 404: Not Found (Kernel does not exist: 972be443-61c2-4ade-8186-3ca3b9aa31fa)
[W 2023-05-23 12:52:43.468 ServerApp] 404 GET /api/kernels/972be443-61c2-4ade-8186-3ca3b9aa31fa?1684817563466 (42442f52999c44fca217868bf36576d9@::1) 1.00ms referer=http://localhost:8888/lab/workspaces/auto-Z/tree/exception.ipynb
[W 2023-05-23 12:53:27.464 ServerApp] 404 GET /api/kernels/e632738a-a9b7-4c57-a212-1e2a49e4e75b/channels?session_id=15e6b46a-2205-43ed-bafa-0217a030c3d0 (::1): Kernel does not exist: e632738a-a9b7-4c57-a212-1e2a49e4e75b
[W 2023-05-23 12:53:27.465 ServerApp] 404 GET /api/kernels/e632738a-a9b7-4c57-a212-1e2a49e4e75b/channels?session_id=15e6b46a-2205-43ed-bafa-0217a030c3d0 (42442f52999c44fca217868bf36576d9@::1) 1.22ms referer=None
[W 2023-05-23 12:53:27.467 ServerApp] 404 GET /api/kernels/e632738a-a9b7-4c57-a212-1e2a49e4e75b?1684817607466 (::1): Kernel does not exist: e632738a-a9b7-4c57-a212-1e2a49e4e75b
[W 2023-05-23 12:53:27.468 ServerApp] wrote error: 'Kernel does not exist: e632738a-a9b7-4c57-a212-1e2a49e4e75b'
    Traceback (most recent call last):
      File "/usr/local/lib/python3.11/site-packages/tornado/web.py", line 1786, in _execute
        result = await result
                 ^^^^^^^^^^^^
      File "/usr/local/lib/python3.11/site-packages/jupyter_server/services/kernels/handlers.py", line 72, in get
        model = await ensure_async(km.kernel_model(kernel_id))
                                   ^^^^^^^^^^^^^^^^^^^^^^^^^^
      File "/usr/local/lib/python3.11/site-packages/jupyter_server/services/kernels/kernelmanager.py", line 496, in kernel_model
        self._check_kernel_id(kernel_id)
      File "/usr/local/lib/python3.11/site-packages/jupyter_server/services/kernels/kernelmanager.py", line 527, in _check_kernel_id
        raise web.HTTPError(404, "Kernel does not exist: %s" % kernel_id)
    tornado.web.HTTPError: HTTP 404: Not Found (Kernel does not exist: e632738a-a9b7-4c57-a212-1e2a49e4e75b)
[W 2023-05-23 12:53:27.468 ServerApp] 404 GET /api/kernels/e632738a-a9b7-4c57-a212-1e2a49e4e75b?1684817607466 (42442f52999c44fca217868bf36576d9@::1) 1.20ms referer=http://localhost:8888/lab/workspaces/auto-6/tree/complexData.ipynb
[I 2023-05-23 17:16:47.925 ServerApp] Kernel started: a03b6df1-01c1-47cd-9830-4a6cba0b1a1c
Traceback (most recent call last):
  File "<frozen runpy>", line 198, in _run_module_as_main
  File "<frozen runpy>", line 88, in _run_code
  File "/usr/local/lib/python3.11/site-packages/ipykernel_launcher.py", line 15, in <module>
    from ipykernel import kernelapp as app
  File "/usr/local/lib/python3.11/site-packages/ipykernel/__init__.py", line 5, in <module>
    from .connect import *  # noqa
    ^^^^^^^^^^^^^^^^^^^^^^
  File "/usr/local/lib/python3.11/site-packages/ipykernel/connect.py", line 11, in <module>
    import jupyter_client
  File "/usr/local/lib/python3.11/site-packages/jupyter_client/__init__.py", line 3, in <module>
    from .asynchronous import AsyncKernelClient
  File "/usr/local/lib/python3.11/site-packages/jupyter_client/asynchronous/__init__.py", line 1, in <module>
    from .client import AsyncKernelClient  # noqa
    ^^^^^^^^^^^^^^^^^^^^^^^^^^^^^^^^^^^^^
  File "/usr/local/lib/python3.11/site-packages/jupyter_client/asynchronous/client.py", line 5, in <module>
    import zmq.asyncio
  File "/usr/local/lib/python3.11/site-packages/zmq/asyncio.py", line 9, in <module>
    import asyncio
  File "/usr/local/Cellar/python@3.11/3.11.3/Frameworks/Python.framework/Versions/3.11/lib/python3.11/asyncio/__init__.py", line 8, in <module>
    from .base_events import *
  File "/usr/local/Cellar/python@3.11/3.11.3/Frameworks/Python.framework/Versions/3.11/lib/python3.11/asyncio/base_events.py", line 18, in <module>
    import concurrent.futures
  File "/Users/zhaoji/Develop/projects/pythonProgram/concurrent.py", line 16
    
    ^
IndentationError: expected an indented block after 'with' statement on line 15
[I 2023-05-23 17:16:50.912 ServerApp] AsyncIOLoopKernelRestarter: restarting kernel (1/5), new random ports
Traceback (most recent call last):
  File "<frozen runpy>", line 198, in _run_module_as_main
  File "<frozen runpy>", line 88, in _run_code
  File "/usr/local/lib/python3.11/site-packages/ipykernel_launcher.py", line 15, in <module>
    from ipykernel import kernelapp as app
  File "/usr/local/lib/python3.11/site-packages/ipykernel/__init__.py", line 5, in <module>
    from .connect import *  # noqa
    ^^^^^^^^^^^^^^^^^^^^^^
  File "/usr/local/lib/python3.11/site-packages/ipykernel/connect.py", line 11, in <module>
    import jupyter_client
  File "/usr/local/lib/python3.11/site-packages/jupyter_client/__init__.py", line 3, in <module>
    from .asynchronous import AsyncKernelClient
  File "/usr/local/lib/python3.11/site-packages/jupyter_client/asynchronous/__init__.py", line 1, in <module>
    from .client import AsyncKernelClient  # noqa
    ^^^^^^^^^^^^^^^^^^^^^^^^^^^^^^^^^^^^^
  File "/usr/local/lib/python3.11/site-packages/jupyter_client/asynchronous/client.py", line 5, in <module>
    import zmq.asyncio
  File "/usr/local/lib/python3.11/site-packages/zmq/asyncio.py", line 9, in <module>
    import asyncio
  File "/usr/local/Cellar/python@3.11/3.11.3/Frameworks/Python.framework/Versions/3.11/lib/python3.11/asyncio/__init__.py", line 8, in <module>
    from .base_events import *
  File "/usr/local/Cellar/python@3.11/3.11.3/Frameworks/Python.framework/Versions/3.11/lib/python3.11/asyncio/base_events.py", line 18, in <module>
    import concurrent.futures
  File "/Users/zhaoji/Develop/projects/pythonProgram/concurrent.py", line 16
    
    ^
IndentationError: expected an indented block after 'with' statement on line 15
[I 2023-05-23 17:16:53.929 ServerApp] AsyncIOLoopKernelRestarter: restarting kernel (2/5), new random ports
Traceback (most recent call last):
  File "<frozen runpy>", line 198, in _run_module_as_main
  File "<frozen runpy>", line 88, in _run_code
  File "/usr/local/lib/python3.11/site-packages/ipykernel_launcher.py", line 15, in <module>
    from ipykernel import kernelapp as app
  File "/usr/local/lib/python3.11/site-packages/ipykernel/__init__.py", line 5, in <module>
    from .connect import *  # noqa
    ^^^^^^^^^^^^^^^^^^^^^^
  File "/usr/local/lib/python3.11/site-packages/ipykernel/connect.py", line 11, in <module>
    import jupyter_client
  File "/usr/local/lib/python3.11/site-packages/jupyter_client/__init__.py", line 3, in <module>
    from .asynchronous import AsyncKernelClient
  File "/usr/local/lib/python3.11/site-packages/jupyter_client/asynchronous/__init__.py", line 1, in <module>
    from .client import AsyncKernelClient  # noqa
    ^^^^^^^^^^^^^^^^^^^^^^^^^^^^^^^^^^^^^
  File "/usr/local/lib/python3.11/site-packages/jupyter_client/asynchronous/client.py", line 5, in <module>
    import zmq.asyncio
  File "/usr/local/lib/python3.11/site-packages/zmq/asyncio.py", line 9, in <module>
    import asyncio
  File "/usr/local/Cellar/python@3.11/3.11.3/Frameworks/Python.framework/Versions/3.11/lib/python3.11/asyncio/__init__.py", line 8, in <module>
    from .base_events import *
  File "/usr/local/Cellar/python@3.11/3.11.3/Frameworks/Python.framework/Versions/3.11/lib/python3.11/asyncio/base_events.py", line 18, in <module>
    import concurrent.futures
  File "/Users/zhaoji/Develop/projects/pythonProgram/concurrent.py", line 16
    
    ^
IndentationError: expected an indented block after 'with' statement on line 15
[I 2023-05-23 17:16:56.946 ServerApp] AsyncIOLoopKernelRestarter: restarting kernel (3/5), new random ports
Traceback (most recent call last):
  File "<frozen runpy>", line 198, in _run_module_as_main
  File "<frozen runpy>", line 88, in _run_code
  File "/usr/local/lib/python3.11/site-packages/ipykernel_launcher.py", line 15, in <module>
    from ipykernel import kernelapp as app
  File "/usr/local/lib/python3.11/site-packages/ipykernel/__init__.py", line 5, in <module>
    from .connect import *  # noqa
    ^^^^^^^^^^^^^^^^^^^^^^
  File "/usr/local/lib/python3.11/site-packages/ipykernel/connect.py", line 11, in <module>
    import jupyter_client
  File "/usr/local/lib/python3.11/site-packages/jupyter_client/__init__.py", line 3, in <module>
    from .asynchronous import AsyncKernelClient
  File "/usr/local/lib/python3.11/site-packages/jupyter_client/asynchronous/__init__.py", line 1, in <module>
    from .client import AsyncKernelClient  # noqa
    ^^^^^^^^^^^^^^^^^^^^^^^^^^^^^^^^^^^^^
  File "/usr/local/lib/python3.11/site-packages/jupyter_client/asynchronous/client.py", line 5, in <module>
    import zmq.asyncio
  File "/usr/local/lib/python3.11/site-packages/zmq/asyncio.py", line 9, in <module>
    import asyncio
  File "/usr/local/Cellar/python@3.11/3.11.3/Frameworks/Python.framework/Versions/3.11/lib/python3.11/asyncio/__init__.py", line 8, in <module>
    from .base_events import *
  File "/usr/local/Cellar/python@3.11/3.11.3/Frameworks/Python.framework/Versions/3.11/lib/python3.11/asyncio/base_events.py", line 18, in <module>
    import concurrent.futures
  File "/Users/zhaoji/Develop/projects/pythonProgram/concurrent.py", line 16
    
    ^
IndentationError: expected an indented block after 'with' statement on line 15
[I 2023-05-23 17:16:59.963 ServerApp] AsyncIOLoopKernelRestarter: restarting kernel (4/5), new random ports
Traceback (most recent call last):
  File "<frozen runpy>", line 198, in _run_module_as_main
  File "<frozen runpy>", line 88, in _run_code
  File "/usr/local/lib/python3.11/site-packages/ipykernel_launcher.py", line 15, in <module>
    from ipykernel import kernelapp as app
  File "/usr/local/lib/python3.11/site-packages/ipykernel/__init__.py", line 5, in <module>
    from .connect import *  # noqa
    ^^^^^^^^^^^^^^^^^^^^^^
  File "/usr/local/lib/python3.11/site-packages/ipykernel/connect.py", line 11, in <module>
    import jupyter_client
  File "/usr/local/lib/python3.11/site-packages/jupyter_client/__init__.py", line 3, in <module>
    from .asynchronous import AsyncKernelClient
  File "/usr/local/lib/python3.11/site-packages/jupyter_client/asynchronous/__init__.py", line 1, in <module>
    from .client import AsyncKernelClient  # noqa
    ^^^^^^^^^^^^^^^^^^^^^^^^^^^^^^^^^^^^^
  File "/usr/local/lib/python3.11/site-packages/jupyter_client/asynchronous/client.py", line 5, in <module>
    import zmq.asyncio
  File "/usr/local/lib/python3.11/site-packages/zmq/asyncio.py", line 9, in <module>
    import asyncio
  File "/usr/local/Cellar/python@3.11/3.11.3/Frameworks/Python.framework/Versions/3.11/lib/python3.11/asyncio/__init__.py", line 8, in <module>
    from .base_events import *
  File "/usr/local/Cellar/python@3.11/3.11.3/Frameworks/Python.framework/Versions/3.11/lib/python3.11/asyncio/base_events.py", line 18, in <module>
    import concurrent.futures
  File "/Users/zhaoji/Develop/projects/pythonProgram/concurrent.py", line 16
    
    ^
IndentationError: expected an indented block after 'with' statement on line 15
[I 2023-05-23 17:17:02.982 ServerApp] AsyncIOLoopKernelRestarter: restarting kernel (5/5), new random ports
Traceback (most recent call last):
  File "<frozen runpy>", line 198, in _run_module_as_main
  File "<frozen runpy>", line 88, in _run_code
  File "/usr/local/lib/python3.11/site-packages/ipykernel_launcher.py", line 15, in <module>
    from ipykernel import kernelapp as app
  File "/usr/local/lib/python3.11/site-packages/ipykernel/__init__.py", line 5, in <module>
    from .connect import *  # noqa
    ^^^^^^^^^^^^^^^^^^^^^^
  File "/usr/local/lib/python3.11/site-packages/ipykernel/connect.py", line 11, in <module>
    import jupyter_client
  File "/usr/local/lib/python3.11/site-packages/jupyter_client/__init__.py", line 3, in <module>
    from .asynchronous import AsyncKernelClient
  File "/usr/local/lib/python3.11/site-packages/jupyter_client/asynchronous/__init__.py", line 1, in <module>
    from .client import AsyncKernelClient  # noqa
    ^^^^^^^^^^^^^^^^^^^^^^^^^^^^^^^^^^^^^
  File "/usr/local/lib/python3.11/site-packages/jupyter_client/asynchronous/client.py", line 5, in <module>
    import zmq.asyncio
  File "/usr/local/lib/python3.11/site-packages/zmq/asyncio.py", line 9, in <module>
    import asyncio
  File "/usr/local/Cellar/python@3.11/3.11.3/Frameworks/Python.framework/Versions/3.11/lib/python3.11/asyncio/__init__.py", line 8, in <module>
    from .base_events import *
  File "/usr/local/Cellar/python@3.11/3.11.3/Frameworks/Python.framework/Versions/3.11/lib/python3.11/asyncio/base_events.py", line 18, in <module>
    import concurrent.futures
  File "/Users/zhaoji/Develop/projects/pythonProgram/concurrent.py", line 16
    
    ^
IndentationError: expected an indented block after 'with' statement on line 15
[W 2023-05-23 17:17:05.999 ServerApp] AsyncIOLoopKernelRestarter: restart failed
[W 2023-05-23 17:17:05.999 ServerApp] Kernel a03b6df1-01c1-47cd-9830-4a6cba0b1a1c died, removing from map.
[I 2023-05-23 17:17:11.234 ServerApp] Kernel started: 4732f480-bca6-4d1d-b52c-32568c656907
Traceback (most recent call last):
  File "<frozen runpy>", line 198, in _run_module_as_main
  File "<frozen runpy>", line 88, in _run_code
  File "/usr/local/lib/python3.11/site-packages/ipykernel_launcher.py", line 15, in <module>
    from ipykernel import kernelapp as app
  File "/usr/local/lib/python3.11/site-packages/ipykernel/__init__.py", line 5, in <module>
    from .connect import *  # noqa
    ^^^^^^^^^^^^^^^^^^^^^^
  File "/usr/local/lib/python3.11/site-packages/ipykernel/connect.py", line 11, in <module>
    import jupyter_client
  File "/usr/local/lib/python3.11/site-packages/jupyter_client/__init__.py", line 3, in <module>
    from .asynchronous import AsyncKernelClient
  File "/usr/local/lib/python3.11/site-packages/jupyter_client/asynchronous/__init__.py", line 1, in <module>
    from .client import AsyncKernelClient  # noqa
    ^^^^^^^^^^^^^^^^^^^^^^^^^^^^^^^^^^^^^
  File "/usr/local/lib/python3.11/site-packages/jupyter_client/asynchronous/client.py", line 5, in <module>
    import zmq.asyncio
  File "/usr/local/lib/python3.11/site-packages/zmq/asyncio.py", line 9, in <module>
    import asyncio
  File "/usr/local/Cellar/python@3.11/3.11.3/Frameworks/Python.framework/Versions/3.11/lib/python3.11/asyncio/__init__.py", line 8, in <module>
    from .base_events import *
  File "/usr/local/Cellar/python@3.11/3.11.3/Frameworks/Python.framework/Versions/3.11/lib/python3.11/asyncio/base_events.py", line 18, in <module>
    import concurrent.futures
  File "/Users/zhaoji/Develop/projects/pythonProgram/concurrent.py", line 16
    
    ^
IndentationError: expected an indented block after 'with' statement on line 15
[I 2023-05-23 17:17:14.222 ServerApp] AsyncIOLoopKernelRestarter: restarting kernel (1/5), new random ports
Traceback (most recent call last):
  File "<frozen runpy>", line 198, in _run_module_as_main
  File "<frozen runpy>", line 88, in _run_code
  File "/usr/local/lib/python3.11/site-packages/ipykernel_launcher.py", line 15, in <module>
    from ipykernel import kernelapp as app
  File "/usr/local/lib/python3.11/site-packages/ipykernel/__init__.py", line 5, in <module>
    from .connect import *  # noqa
    ^^^^^^^^^^^^^^^^^^^^^^
  File "/usr/local/lib/python3.11/site-packages/ipykernel/connect.py", line 11, in <module>
    import jupyter_client
  File "/usr/local/lib/python3.11/site-packages/jupyter_client/__init__.py", line 3, in <module>
    from .asynchronous import AsyncKernelClient
  File "/usr/local/lib/python3.11/site-packages/jupyter_client/asynchronous/__init__.py", line 1, in <module>
    from .client import AsyncKernelClient  # noqa
    ^^^^^^^^^^^^^^^^^^^^^^^^^^^^^^^^^^^^^
  File "/usr/local/lib/python3.11/site-packages/jupyter_client/asynchronous/client.py", line 5, in <module>
    import zmq.asyncio
  File "/usr/local/lib/python3.11/site-packages/zmq/asyncio.py", line 9, in <module>
    import asyncio
  File "/usr/local/Cellar/python@3.11/3.11.3/Frameworks/Python.framework/Versions/3.11/lib/python3.11/asyncio/__init__.py", line 8, in <module>
    from .base_events import *
  File "/usr/local/Cellar/python@3.11/3.11.3/Frameworks/Python.framework/Versions/3.11/lib/python3.11/asyncio/base_events.py", line 18, in <module>
    import concurrent.futures
  File "/Users/zhaoji/Develop/projects/pythonProgram/concurrent.py", line 16
    
    ^
IndentationError: expected an indented block after 'with' statement on line 15
[I 2023-05-23 17:17:17.243 ServerApp] AsyncIOLoopKernelRestarter: restarting kernel (2/5), new random ports
Traceback (most recent call last):
  File "<frozen runpy>", line 198, in _run_module_as_main
  File "<frozen runpy>", line 88, in _run_code
  File "/usr/local/lib/python3.11/site-packages/ipykernel_launcher.py", line 15, in <module>
    from ipykernel import kernelapp as app
  File "/usr/local/lib/python3.11/site-packages/ipykernel/__init__.py", line 5, in <module>
    from .connect import *  # noqa
    ^^^^^^^^^^^^^^^^^^^^^^
  File "/usr/local/lib/python3.11/site-packages/ipykernel/connect.py", line 11, in <module>
    import jupyter_client
  File "/usr/local/lib/python3.11/site-packages/jupyter_client/__init__.py", line 3, in <module>
    from .asynchronous import AsyncKernelClient
  File "/usr/local/lib/python3.11/site-packages/jupyter_client/asynchronous/__init__.py", line 1, in <module>
    from .client import AsyncKernelClient  # noqa
    ^^^^^^^^^^^^^^^^^^^^^^^^^^^^^^^^^^^^^
  File "/usr/local/lib/python3.11/site-packages/jupyter_client/asynchronous/client.py", line 5, in <module>
    import zmq.asyncio
  File "/usr/local/lib/python3.11/site-packages/zmq/asyncio.py", line 9, in <module>
    import asyncio
  File "/usr/local/Cellar/python@3.11/3.11.3/Frameworks/Python.framework/Versions/3.11/lib/python3.11/asyncio/__init__.py", line 8, in <module>
    from .base_events import *
  File "/usr/local/Cellar/python@3.11/3.11.3/Frameworks/Python.framework/Versions/3.11/lib/python3.11/asyncio/base_events.py", line 18, in <module>
    import concurrent.futures
  File "/Users/zhaoji/Develop/projects/pythonProgram/concurrent.py", line 16
    
    ^
IndentationError: expected an indented block after 'with' statement on line 15
[I 2023-05-23 17:17:20.261 ServerApp] AsyncIOLoopKernelRestarter: restarting kernel (3/5), new random ports
Traceback (most recent call last):
  File "<frozen runpy>", line 198, in _run_module_as_main
  File "<frozen runpy>", line 88, in _run_code
  File "/usr/local/lib/python3.11/site-packages/ipykernel_launcher.py", line 15, in <module>
    from ipykernel import kernelapp as app
  File "/usr/local/lib/python3.11/site-packages/ipykernel/__init__.py", line 5, in <module>
    from .connect import *  # noqa
    ^^^^^^^^^^^^^^^^^^^^^^
  File "/usr/local/lib/python3.11/site-packages/ipykernel/connect.py", line 11, in <module>
    import jupyter_client
  File "/usr/local/lib/python3.11/site-packages/jupyter_client/__init__.py", line 3, in <module>
    from .asynchronous import AsyncKernelClient
  File "/usr/local/lib/python3.11/site-packages/jupyter_client/asynchronous/__init__.py", line 1, in <module>
    from .client import AsyncKernelClient  # noqa
    ^^^^^^^^^^^^^^^^^^^^^^^^^^^^^^^^^^^^^
  File "/usr/local/lib/python3.11/site-packages/jupyter_client/asynchronous/client.py", line 5, in <module>
    import zmq.asyncio
  File "/usr/local/lib/python3.11/site-packages/zmq/asyncio.py", line 9, in <module>
    import asyncio
  File "/usr/local/Cellar/python@3.11/3.11.3/Frameworks/Python.framework/Versions/3.11/lib/python3.11/asyncio/__init__.py", line 8, in <module>
    from .base_events import *
  File "/usr/local/Cellar/python@3.11/3.11.3/Frameworks/Python.framework/Versions/3.11/lib/python3.11/asyncio/base_events.py", line 18, in <module>
    import concurrent.futures
  File "/Users/zhaoji/Develop/projects/pythonProgram/concurrent.py", line 16
    
    ^
IndentationError: expected an indented block after 'with' statement on line 15
[I 2023-05-23 17:17:23.281 ServerApp] AsyncIOLoopKernelRestarter: restarting kernel (4/5), new random ports
Traceback (most recent call last):
  File "<frozen runpy>", line 198, in _run_module_as_main
  File "<frozen runpy>", line 88, in _run_code
  File "/usr/local/lib/python3.11/site-packages/ipykernel_launcher.py", line 15, in <module>
    from ipykernel import kernelapp as app
  File "/usr/local/lib/python3.11/site-packages/ipykernel/__init__.py", line 5, in <module>
    from .connect import *  # noqa
    ^^^^^^^^^^^^^^^^^^^^^^
  File "/usr/local/lib/python3.11/site-packages/ipykernel/connect.py", line 11, in <module>
    import jupyter_client
  File "/usr/local/lib/python3.11/site-packages/jupyter_client/__init__.py", line 3, in <module>
    from .asynchronous import AsyncKernelClient
  File "/usr/local/lib/python3.11/site-packages/jupyter_client/asynchronous/__init__.py", line 1, in <module>
    from .client import AsyncKernelClient  # noqa
    ^^^^^^^^^^^^^^^^^^^^^^^^^^^^^^^^^^^^^
  File "/usr/local/lib/python3.11/site-packages/jupyter_client/asynchronous/client.py", line 5, in <module>
    import zmq.asyncio
  File "/usr/local/lib/python3.11/site-packages/zmq/asyncio.py", line 9, in <module>
    import asyncio
  File "/usr/local/Cellar/python@3.11/3.11.3/Frameworks/Python.framework/Versions/3.11/lib/python3.11/asyncio/__init__.py", line 8, in <module>
    from .base_events import *
  File "/usr/local/Cellar/python@3.11/3.11.3/Frameworks/Python.framework/Versions/3.11/lib/python3.11/asyncio/base_events.py", line 18, in <module>
    import concurrent.futures
  File "/Users/zhaoji/Develop/projects/pythonProgram/concurrent.py", line 16
    
    ^
IndentationError: expected an indented block after 'with' statement on line 15
[I 2023-05-23 17:17:26.300 ServerApp] AsyncIOLoopKernelRestarter: restarting kernel (5/5), new random ports
Traceback (most recent call last):
  File "<frozen runpy>", line 198, in _run_module_as_main
  File "<frozen runpy>", line 88, in _run_code
  File "/usr/local/lib/python3.11/site-packages/ipykernel_launcher.py", line 15, in <module>
    from ipykernel import kernelapp as app
  File "/usr/local/lib/python3.11/site-packages/ipykernel/__init__.py", line 5, in <module>
    from .connect import *  # noqa
    ^^^^^^^^^^^^^^^^^^^^^^
  File "/usr/local/lib/python3.11/site-packages/ipykernel/connect.py", line 11, in <module>
    import jupyter_client
  File "/usr/local/lib/python3.11/site-packages/jupyter_client/__init__.py", line 3, in <module>
    from .asynchronous import AsyncKernelClient
  File "/usr/local/lib/python3.11/site-packages/jupyter_client/asynchronous/__init__.py", line 1, in <module>
    from .client import AsyncKernelClient  # noqa
    ^^^^^^^^^^^^^^^^^^^^^^^^^^^^^^^^^^^^^
  File "/usr/local/lib/python3.11/site-packages/jupyter_client/asynchronous/client.py", line 5, in <module>
    import zmq.asyncio
  File "/usr/local/lib/python3.11/site-packages/zmq/asyncio.py", line 9, in <module>
    import asyncio
  File "/usr/local/Cellar/python@3.11/3.11.3/Frameworks/Python.framework/Versions/3.11/lib/python3.11/asyncio/__init__.py", line 8, in <module>
    from .base_events import *
  File "/usr/local/Cellar/python@3.11/3.11.3/Frameworks/Python.framework/Versions/3.11/lib/python3.11/asyncio/base_events.py", line 18, in <module>
    import concurrent.futures
  File "/Users/zhaoji/Develop/projects/pythonProgram/concurrent.py", line 16
    
    ^
IndentationError: expected an indented block after 'with' statement on line 15
[W 2023-05-23 17:17:29.319 ServerApp] AsyncIOLoopKernelRestarter: restart failed
[W 2023-05-23 17:17:29.319 ServerApp] Kernel 4732f480-bca6-4d1d-b52c-32568c656907 died, removing from map.
[W 2023-05-23 17:17:47.957 ServerApp] Timeout waiting for kernel_info reply from a03b6df1-01c1-47cd-9830-4a6cba0b1a1c
[E 2023-05-23 17:17:47.958 ServerApp] Uncaught exception GET /api/kernels/a03b6df1-01c1-47cd-9830-4a6cba0b1a1c/channels?session_id=698eef6f-e13a-4ade-9c76-f8bb83773416 (::1)
    HTTPServerRequest(protocol='http', host='localhost:8888', method='GET', uri='/api/kernels/a03b6df1-01c1-47cd-9830-4a6cba0b1a1c/channels?session_id=698eef6f-e13a-4ade-9c76-f8bb83773416', version='HTTP/1.1', remote_ip='::1')
    Traceback (most recent call last):
      File "/usr/local/lib/python3.11/site-packages/tornado/web.py", line 1786, in _execute
        result = await result
                 ^^^^^^^^^^^^
      File "/usr/local/lib/python3.11/site-packages/jupyter_server/services/kernels/websocket.py", line 67, in get
        await super().get(kernel_id=kernel_id)
      File "/usr/local/lib/python3.11/site-packages/tornado/websocket.py", line 272, in get
        await self.ws_connection.accept_connection(self)
      File "/usr/local/lib/python3.11/site-packages/tornado/websocket.py", line 862, in accept_connection
        await self._accept_connection(handler)
      File "/usr/local/lib/python3.11/site-packages/tornado/websocket.py", line 902, in _accept_connection
        self.selected_subprotocol = handler.select_subprotocol(subprotocols)
                                    ^^^^^^^^^^^^^^^^^^^^^^^^^^^^^^^^^^^^^^^^
      File "/usr/local/lib/python3.11/site-packages/jupyter_server/services/kernels/websocket.py", line 86, in select_subprotocol
        preferred_protocol = self.connection.kernel_ws_protocol
                             ^^^^^^^^^^^^^^^^^^^^^^^^^^^^^^^^^^
    AttributeError: 'NoneType' object has no attribute 'kernel_ws_protocol'
[E 2023-05-23 17:17:47.969 ServerApp] {
      "Host": "localhost:8888",
      "User-Agent": "Mozilla/5.0 (Macintosh; Intel Mac OS X 10_15_7) AppleWebKit/537.36 (KHTML, like Gecko) Chrome/113.0.0.0 Safari/537.36"
    }
[E 2023-05-23 17:17:47.969 ServerApp] 500 GET /api/kernels/a03b6df1-01c1-47cd-9830-4a6cba0b1a1c/channels?session_id=698eef6f-e13a-4ade-9c76-f8bb83773416 (42442f52999c44fca217868bf36576d9@::1) 60017.22ms referer=None
[W 2023-05-23 17:18:11.266 ServerApp] Timeout waiting for kernel_info reply from 4732f480-bca6-4d1d-b52c-32568c656907
[E 2023-05-23 17:18:11.266 ServerApp] Uncaught exception GET /api/kernels/4732f480-bca6-4d1d-b52c-32568c656907/channels?session_id=a18c7d0a-0980-4f7a-9c2a-fc66b289d788 (::1)
    HTTPServerRequest(protocol='http', host='localhost:8888', method='GET', uri='/api/kernels/4732f480-bca6-4d1d-b52c-32568c656907/channels?session_id=a18c7d0a-0980-4f7a-9c2a-fc66b289d788', version='HTTP/1.1', remote_ip='::1')
    Traceback (most recent call last):
      File "/usr/local/lib/python3.11/site-packages/tornado/web.py", line 1786, in _execute
        result = await result
                 ^^^^^^^^^^^^
      File "/usr/local/lib/python3.11/site-packages/jupyter_server/services/kernels/websocket.py", line 67, in get
        await super().get(kernel_id=kernel_id)
      File "/usr/local/lib/python3.11/site-packages/tornado/websocket.py", line 272, in get
        await self.ws_connection.accept_connection(self)
      File "/usr/local/lib/python3.11/site-packages/tornado/websocket.py", line 862, in accept_connection
        await self._accept_connection(handler)
      File "/usr/local/lib/python3.11/site-packages/tornado/websocket.py", line 902, in _accept_connection
        self.selected_subprotocol = handler.select_subprotocol(subprotocols)
                                    ^^^^^^^^^^^^^^^^^^^^^^^^^^^^^^^^^^^^^^^^
      File "/usr/local/lib/python3.11/site-packages/jupyter_server/services/kernels/websocket.py", line 86, in select_subprotocol
        preferred_protocol = self.connection.kernel_ws_protocol
                             ^^^^^^^^^^^^^^^^^^^^^^^^^^^^^^^^^^
    AttributeError: 'NoneType' object has no attribute 'kernel_ws_protocol'
[E 2023-05-23 17:18:11.268 ServerApp] {
      "Host": "localhost:8888",
      "User-Agent": "Mozilla/5.0 (Macintosh; Intel Mac OS X 10_15_7) AppleWebKit/537.36 (KHTML, like Gecko) Chrome/113.0.0.0 Safari/537.36"
    }
[E 2023-05-23 17:18:11.269 ServerApp] 500 GET /api/kernels/4732f480-bca6-4d1d-b52c-32568c656907/channels?session_id=a18c7d0a-0980-4f7a-9c2a-fc66b289d788 (42442f52999c44fca217868bf36576d9@::1) 60007.28ms referer=None
[I 2023-05-23 17:18:43.598 ServerApp] Saving file at /complexData.ipynb
[I 2023-05-23 17:38:12.883 ServerApp] Kernel started: 864b4a7b-c6b4-4088-988c-13d93f8bfd80
Traceback (most recent call last):
  File "<frozen runpy>", line 198, in _run_module_as_main
  File "<frozen runpy>", line 88, in _run_code
  File "/usr/local/lib/python3.11/site-packages/ipykernel_launcher.py", line 15, in <module>
    from ipykernel import kernelapp as app
  File "/usr/local/lib/python3.11/site-packages/ipykernel/__init__.py", line 5, in <module>
    from .connect import *  # noqa
    ^^^^^^^^^^^^^^^^^^^^^^
  File "/usr/local/lib/python3.11/site-packages/ipykernel/connect.py", line 11, in <module>
    import jupyter_client
  File "/usr/local/lib/python3.11/site-packages/jupyter_client/__init__.py", line 3, in <module>
    from .asynchronous import AsyncKernelClient
  File "/usr/local/lib/python3.11/site-packages/jupyter_client/asynchronous/__init__.py", line 1, in <module>
    from .client import AsyncKernelClient  # noqa
    ^^^^^^^^^^^^^^^^^^^^^^^^^^^^^^^^^^^^^
  File "/usr/local/lib/python3.11/site-packages/jupyter_client/asynchronous/client.py", line 5, in <module>
    import zmq.asyncio
  File "/usr/local/lib/python3.11/site-packages/zmq/asyncio.py", line 9, in <module>
    import asyncio
  File "/usr/local/Cellar/python@3.11/3.11.3/Frameworks/Python.framework/Versions/3.11/lib/python3.11/asyncio/__init__.py", line 8, in <module>
    from .base_events import *
  File "/usr/local/Cellar/python@3.11/3.11.3/Frameworks/Python.framework/Versions/3.11/lib/python3.11/asyncio/base_events.py", line 18, in <module>
    import concurrent.futures
  File "/Users/zhaoji/Develop/projects/pythonProgram/concurrent.py", line 16
    
    ^
IndentationError: expected an indented block after 'with' statement on line 15
[I 2023-05-23 17:38:15.870 ServerApp] AsyncIOLoopKernelRestarter: restarting kernel (1/5), new random ports
Traceback (most recent call last):
  File "<frozen runpy>", line 198, in _run_module_as_main
  File "<frozen runpy>", line 88, in _run_code
  File "/usr/local/lib/python3.11/site-packages/ipykernel_launcher.py", line 15, in <module>
    from ipykernel import kernelapp as app
  File "/usr/local/lib/python3.11/site-packages/ipykernel/__init__.py", line 5, in <module>
    from .connect import *  # noqa
    ^^^^^^^^^^^^^^^^^^^^^^
  File "/usr/local/lib/python3.11/site-packages/ipykernel/connect.py", line 11, in <module>
    import jupyter_client
  File "/usr/local/lib/python3.11/site-packages/jupyter_client/__init__.py", line 3, in <module>
    from .asynchronous import AsyncKernelClient
  File "/usr/local/lib/python3.11/site-packages/jupyter_client/asynchronous/__init__.py", line 1, in <module>
    from .client import AsyncKernelClient  # noqa
    ^^^^^^^^^^^^^^^^^^^^^^^^^^^^^^^^^^^^^
  File "/usr/local/lib/python3.11/site-packages/jupyter_client/asynchronous/client.py", line 5, in <module>
    import zmq.asyncio
  File "/usr/local/lib/python3.11/site-packages/zmq/asyncio.py", line 9, in <module>
    import asyncio
  File "/usr/local/Cellar/python@3.11/3.11.3/Frameworks/Python.framework/Versions/3.11/lib/python3.11/asyncio/__init__.py", line 8, in <module>
    from .base_events import *
  File "/usr/local/Cellar/python@3.11/3.11.3/Frameworks/Python.framework/Versions/3.11/lib/python3.11/asyncio/base_events.py", line 18, in <module>
    import concurrent.futures
  File "/Users/zhaoji/Develop/projects/pythonProgram/concurrent.py", line 16
    
    ^
IndentationError: expected an indented block after 'with' statement on line 15
[I 2023-05-23 17:38:18.888 ServerApp] AsyncIOLoopKernelRestarter: restarting kernel (2/5), new random ports
Traceback (most recent call last):
  File "<frozen runpy>", line 198, in _run_module_as_main
  File "<frozen runpy>", line 88, in _run_code
  File "/usr/local/lib/python3.11/site-packages/ipykernel_launcher.py", line 15, in <module>
    from ipykernel import kernelapp as app
  File "/usr/local/lib/python3.11/site-packages/ipykernel/__init__.py", line 5, in <module>
    from .connect import *  # noqa
    ^^^^^^^^^^^^^^^^^^^^^^
  File "/usr/local/lib/python3.11/site-packages/ipykernel/connect.py", line 11, in <module>
    import jupyter_client
  File "/usr/local/lib/python3.11/site-packages/jupyter_client/__init__.py", line 3, in <module>
    from .asynchronous import AsyncKernelClient
  File "/usr/local/lib/python3.11/site-packages/jupyter_client/asynchronous/__init__.py", line 1, in <module>
    from .client import AsyncKernelClient  # noqa
    ^^^^^^^^^^^^^^^^^^^^^^^^^^^^^^^^^^^^^
  File "/usr/local/lib/python3.11/site-packages/jupyter_client/asynchronous/client.py", line 5, in <module>
    import zmq.asyncio
  File "/usr/local/lib/python3.11/site-packages/zmq/asyncio.py", line 9, in <module>
    import asyncio
  File "/usr/local/Cellar/python@3.11/3.11.3/Frameworks/Python.framework/Versions/3.11/lib/python3.11/asyncio/__init__.py", line 8, in <module>
    from .base_events import *
  File "/usr/local/Cellar/python@3.11/3.11.3/Frameworks/Python.framework/Versions/3.11/lib/python3.11/asyncio/base_events.py", line 18, in <module>
    import concurrent.futures
  File "/Users/zhaoji/Develop/projects/pythonProgram/concurrent.py", line 16
    
    ^
IndentationError: expected an indented block after 'with' statement on line 15
[I 2023-05-23 17:38:21.908 ServerApp] AsyncIOLoopKernelRestarter: restarting kernel (3/5), new random ports
Traceback (most recent call last):
  File "<frozen runpy>", line 198, in _run_module_as_main
  File "<frozen runpy>", line 88, in _run_code
  File "/usr/local/lib/python3.11/site-packages/ipykernel_launcher.py", line 15, in <module>
    from ipykernel import kernelapp as app
  File "/usr/local/lib/python3.11/site-packages/ipykernel/__init__.py", line 5, in <module>
    from .connect import *  # noqa
    ^^^^^^^^^^^^^^^^^^^^^^
  File "/usr/local/lib/python3.11/site-packages/ipykernel/connect.py", line 11, in <module>
    import jupyter_client
  File "/usr/local/lib/python3.11/site-packages/jupyter_client/__init__.py", line 3, in <module>
    from .asynchronous import AsyncKernelClient
  File "/usr/local/lib/python3.11/site-packages/jupyter_client/asynchronous/__init__.py", line 1, in <module>
    from .client import AsyncKernelClient  # noqa
    ^^^^^^^^^^^^^^^^^^^^^^^^^^^^^^^^^^^^^
  File "/usr/local/lib/python3.11/site-packages/jupyter_client/asynchronous/client.py", line 5, in <module>
    import zmq.asyncio
  File "/usr/local/lib/python3.11/site-packages/zmq/asyncio.py", line 9, in <module>
    import asyncio
  File "/usr/local/Cellar/python@3.11/3.11.3/Frameworks/Python.framework/Versions/3.11/lib/python3.11/asyncio/__init__.py", line 8, in <module>
    from .base_events import *
  File "/usr/local/Cellar/python@3.11/3.11.3/Frameworks/Python.framework/Versions/3.11/lib/python3.11/asyncio/base_events.py", line 18, in <module>
    import concurrent.futures
  File "/Users/zhaoji/Develop/projects/pythonProgram/concurrent.py", line 16
    
    ^
IndentationError: expected an indented block after 'with' statement on line 15
[I 2023-05-23 17:38:24.925 ServerApp] AsyncIOLoopKernelRestarter: restarting kernel (4/5), new random ports
Traceback (most recent call last):
  File "<frozen runpy>", line 198, in _run_module_as_main
  File "<frozen runpy>", line 88, in _run_code
  File "/usr/local/lib/python3.11/site-packages/ipykernel_launcher.py", line 15, in <module>
    from ipykernel import kernelapp as app
  File "/usr/local/lib/python3.11/site-packages/ipykernel/__init__.py", line 5, in <module>
    from .connect import *  # noqa
    ^^^^^^^^^^^^^^^^^^^^^^
  File "/usr/local/lib/python3.11/site-packages/ipykernel/connect.py", line 11, in <module>
    import jupyter_client
  File "/usr/local/lib/python3.11/site-packages/jupyter_client/__init__.py", line 3, in <module>
    from .asynchronous import AsyncKernelClient
  File "/usr/local/lib/python3.11/site-packages/jupyter_client/asynchronous/__init__.py", line 1, in <module>
    from .client import AsyncKernelClient  # noqa
    ^^^^^^^^^^^^^^^^^^^^^^^^^^^^^^^^^^^^^
  File "/usr/local/lib/python3.11/site-packages/jupyter_client/asynchronous/client.py", line 5, in <module>
    import zmq.asyncio
  File "/usr/local/lib/python3.11/site-packages/zmq/asyncio.py", line 9, in <module>
    import asyncio
  File "/usr/local/Cellar/python@3.11/3.11.3/Frameworks/Python.framework/Versions/3.11/lib/python3.11/asyncio/__init__.py", line 8, in <module>
    from .base_events import *
  File "/usr/local/Cellar/python@3.11/3.11.3/Frameworks/Python.framework/Versions/3.11/lib/python3.11/asyncio/base_events.py", line 18, in <module>
    import concurrent.futures
  File "/Users/zhaoji/Develop/projects/pythonProgram/concurrent.py", line 16
    
    ^
IndentationError: expected an indented block after 'with' statement on line 15
[I 2023-05-23 17:38:27.943 ServerApp] AsyncIOLoopKernelRestarter: restarting kernel (5/5), new random ports
Traceback (most recent call last):
  File "<frozen runpy>", line 198, in _run_module_as_main
  File "<frozen runpy>", line 88, in _run_code
  File "/usr/local/lib/python3.11/site-packages/ipykernel_launcher.py", line 15, in <module>
    from ipykernel import kernelapp as app
  File "/usr/local/lib/python3.11/site-packages/ipykernel/__init__.py", line 5, in <module>
    from .connect import *  # noqa
    ^^^^^^^^^^^^^^^^^^^^^^
  File "/usr/local/lib/python3.11/site-packages/ipykernel/connect.py", line 11, in <module>
    import jupyter_client
  File "/usr/local/lib/python3.11/site-packages/jupyter_client/__init__.py", line 3, in <module>
    from .asynchronous import AsyncKernelClient
  File "/usr/local/lib/python3.11/site-packages/jupyter_client/asynchronous/__init__.py", line 1, in <module>
    from .client import AsyncKernelClient  # noqa
    ^^^^^^^^^^^^^^^^^^^^^^^^^^^^^^^^^^^^^
  File "/usr/local/lib/python3.11/site-packages/jupyter_client/asynchronous/client.py", line 5, in <module>
    import zmq.asyncio
  File "/usr/local/lib/python3.11/site-packages/zmq/asyncio.py", line 9, in <module>
    import asyncio
  File "/usr/local/Cellar/python@3.11/3.11.3/Frameworks/Python.framework/Versions/3.11/lib/python3.11/asyncio/__init__.py", line 8, in <module>
    from .base_events import *
  File "/usr/local/Cellar/python@3.11/3.11.3/Frameworks/Python.framework/Versions/3.11/lib/python3.11/asyncio/base_events.py", line 18, in <module>
    import concurrent.futures
  File "/Users/zhaoji/Develop/projects/pythonProgram/concurrent.py", line 16
    
    ^
IndentationError: expected an indented block after 'with' statement on line 15
[W 2023-05-23 17:38:30.961 ServerApp] AsyncIOLoopKernelRestarter: restart failed
[W 2023-05-23 17:38:30.961 ServerApp] Kernel 864b4a7b-c6b4-4088-988c-13d93f8bfd80 died, removing from map.
[I 2023-05-23 17:38:44.211 ServerApp] Saving file at /complexData.ipynb
[W 2023-05-23 17:39:13.000 ServerApp] Timeout waiting for kernel_info reply from 864b4a7b-c6b4-4088-988c-13d93f8bfd80
[E 2023-05-23 17:39:13.001 ServerApp] Uncaught exception GET /api/kernels/864b4a7b-c6b4-4088-988c-13d93f8bfd80/channels?session_id=82880d75-c9eb-4bf2-95c0-54f5cf4a18ff (::1)
    HTTPServerRequest(protocol='http', host='localhost:8888', method='GET', uri='/api/kernels/864b4a7b-c6b4-4088-988c-13d93f8bfd80/channels?session_id=82880d75-c9eb-4bf2-95c0-54f5cf4a18ff', version='HTTP/1.1', remote_ip='::1')
    Traceback (most recent call last):
      File "/usr/local/lib/python3.11/site-packages/tornado/web.py", line 1786, in _execute
        result = await result
                 ^^^^^^^^^^^^
      File "/usr/local/lib/python3.11/site-packages/jupyter_server/services/kernels/websocket.py", line 67, in get
        await super().get(kernel_id=kernel_id)
      File "/usr/local/lib/python3.11/site-packages/tornado/websocket.py", line 272, in get
        await self.ws_connection.accept_connection(self)
      File "/usr/local/lib/python3.11/site-packages/tornado/websocket.py", line 862, in accept_connection
        await self._accept_connection(handler)
      File "/usr/local/lib/python3.11/site-packages/tornado/websocket.py", line 902, in _accept_connection
        self.selected_subprotocol = handler.select_subprotocol(subprotocols)
                                    ^^^^^^^^^^^^^^^^^^^^^^^^^^^^^^^^^^^^^^^^
      File "/usr/local/lib/python3.11/site-packages/jupyter_server/services/kernels/websocket.py", line 86, in select_subprotocol
        preferred_protocol = self.connection.kernel_ws_protocol
                             ^^^^^^^^^^^^^^^^^^^^^^^^^^^^^^^^^^
    AttributeError: 'NoneType' object has no attribute 'kernel_ws_protocol'
[E 2023-05-23 17:39:13.004 ServerApp] {
      "Host": "localhost:8888",
      "User-Agent": "Mozilla/5.0 (Macintosh; Intel Mac OS X 10_15_7) AppleWebKit/537.36 (KHTML, like Gecko) Chrome/113.0.0.0 Safari/537.36"
    }
[E 2023-05-23 17:39:13.004 ServerApp] 500 GET /api/kernels/864b4a7b-c6b4-4088-988c-13d93f8bfd80/channels?session_id=82880d75-c9eb-4bf2-95c0-54f5cf4a18ff (42442f52999c44fca217868bf36576d9@::1) 60008.74ms referer=None
[I 2023-05-23 17:46:10.925 ServerApp] Kernel started: 3f384291-a80c-4ceb-8579-731549e2b29d
Traceback (most recent call last):
  File "<frozen runpy>", line 198, in _run_module_as_main
  File "<frozen runpy>", line 88, in _run_code
  File "/usr/local/lib/python3.11/site-packages/ipykernel_launcher.py", line 15, in <module>
    from ipykernel import kernelapp as app
  File "/usr/local/lib/python3.11/site-packages/ipykernel/__init__.py", line 5, in <module>
    from .connect import *  # noqa
    ^^^^^^^^^^^^^^^^^^^^^^
  File "/usr/local/lib/python3.11/site-packages/ipykernel/connect.py", line 11, in <module>
    import jupyter_client
  File "/usr/local/lib/python3.11/site-packages/jupyter_client/__init__.py", line 3, in <module>
    from .asynchronous import AsyncKernelClient
  File "/usr/local/lib/python3.11/site-packages/jupyter_client/asynchronous/__init__.py", line 1, in <module>
    from .client import AsyncKernelClient  # noqa
    ^^^^^^^^^^^^^^^^^^^^^^^^^^^^^^^^^^^^^
  File "/usr/local/lib/python3.11/site-packages/jupyter_client/asynchronous/client.py", line 5, in <module>
    import zmq.asyncio
  File "/usr/local/lib/python3.11/site-packages/zmq/asyncio.py", line 9, in <module>
    import asyncio
  File "/usr/local/Cellar/python@3.11/3.11.3/Frameworks/Python.framework/Versions/3.11/lib/python3.11/asyncio/__init__.py", line 8, in <module>
    from .base_events import *
  File "/usr/local/Cellar/python@3.11/3.11.3/Frameworks/Python.framework/Versions/3.11/lib/python3.11/asyncio/base_events.py", line 18, in <module>
    import concurrent.futures
  File "/Users/zhaoji/Develop/projects/pythonProgram/concurrent.py", line 16
    
    ^
IndentationError: expected an indented block after 'with' statement on line 15
[I 2023-05-23 17:46:13.913 ServerApp] AsyncIOLoopKernelRestarter: restarting kernel (1/5), new random ports
Traceback (most recent call last):
  File "<frozen runpy>", line 198, in _run_module_as_main
  File "<frozen runpy>", line 88, in _run_code
  File "/usr/local/lib/python3.11/site-packages/ipykernel_launcher.py", line 15, in <module>
    from ipykernel import kernelapp as app
  File "/usr/local/lib/python3.11/site-packages/ipykernel/__init__.py", line 5, in <module>
    from .connect import *  # noqa
    ^^^^^^^^^^^^^^^^^^^^^^
  File "/usr/local/lib/python3.11/site-packages/ipykernel/connect.py", line 11, in <module>
    import jupyter_client
  File "/usr/local/lib/python3.11/site-packages/jupyter_client/__init__.py", line 3, in <module>
    from .asynchronous import AsyncKernelClient
  File "/usr/local/lib/python3.11/site-packages/jupyter_client/asynchronous/__init__.py", line 1, in <module>
    from .client import AsyncKernelClient  # noqa
    ^^^^^^^^^^^^^^^^^^^^^^^^^^^^^^^^^^^^^
  File "/usr/local/lib/python3.11/site-packages/jupyter_client/asynchronous/client.py", line 5, in <module>
    import zmq.asyncio
  File "/usr/local/lib/python3.11/site-packages/zmq/asyncio.py", line 9, in <module>
    import asyncio
  File "/usr/local/Cellar/python@3.11/3.11.3/Frameworks/Python.framework/Versions/3.11/lib/python3.11/asyncio/__init__.py", line 8, in <module>
    from .base_events import *
  File "/usr/local/Cellar/python@3.11/3.11.3/Frameworks/Python.framework/Versions/3.11/lib/python3.11/asyncio/base_events.py", line 18, in <module>
    import concurrent.futures
  File "/Users/zhaoji/Develop/projects/pythonProgram/concurrent.py", line 16
    
    ^
IndentationError: expected an indented block after 'with' statement on line 15
[I 2023-05-23 17:46:16.931 ServerApp] AsyncIOLoopKernelRestarter: restarting kernel (2/5), new random ports
Traceback (most recent call last):
  File "<frozen runpy>", line 198, in _run_module_as_main
  File "<frozen runpy>", line 88, in _run_code
  File "/usr/local/lib/python3.11/site-packages/ipykernel_launcher.py", line 15, in <module>
    from ipykernel import kernelapp as app
  File "/usr/local/lib/python3.11/site-packages/ipykernel/__init__.py", line 5, in <module>
    from .connect import *  # noqa
    ^^^^^^^^^^^^^^^^^^^^^^
  File "/usr/local/lib/python3.11/site-packages/ipykernel/connect.py", line 11, in <module>
    import jupyter_client
  File "/usr/local/lib/python3.11/site-packages/jupyter_client/__init__.py", line 3, in <module>
    from .asynchronous import AsyncKernelClient
  File "/usr/local/lib/python3.11/site-packages/jupyter_client/asynchronous/__init__.py", line 1, in <module>
    from .client import AsyncKernelClient  # noqa
    ^^^^^^^^^^^^^^^^^^^^^^^^^^^^^^^^^^^^^
  File "/usr/local/lib/python3.11/site-packages/jupyter_client/asynchronous/client.py", line 5, in <module>
    import zmq.asyncio
  File "/usr/local/lib/python3.11/site-packages/zmq/asyncio.py", line 9, in <module>
    import asyncio
  File "/usr/local/Cellar/python@3.11/3.11.3/Frameworks/Python.framework/Versions/3.11/lib/python3.11/asyncio/__init__.py", line 8, in <module>
    from .base_events import *
  File "/usr/local/Cellar/python@3.11/3.11.3/Frameworks/Python.framework/Versions/3.11/lib/python3.11/asyncio/base_events.py", line 18, in <module>
    import concurrent.futures
  File "/Users/zhaoji/Develop/projects/pythonProgram/concurrent.py", line 16
    
    ^
IndentationError: expected an indented block after 'with' statement on line 15
[I 2023-05-23 17:46:19.950 ServerApp] AsyncIOLoopKernelRestarter: restarting kernel (3/5), new random ports
Traceback (most recent call last):
  File "<frozen runpy>", line 198, in _run_module_as_main
  File "<frozen runpy>", line 88, in _run_code
  File "/usr/local/lib/python3.11/site-packages/ipykernel_launcher.py", line 15, in <module>
    from ipykernel import kernelapp as app
  File "/usr/local/lib/python3.11/site-packages/ipykernel/__init__.py", line 5, in <module>
    from .connect import *  # noqa
    ^^^^^^^^^^^^^^^^^^^^^^
  File "/usr/local/lib/python3.11/site-packages/ipykernel/connect.py", line 11, in <module>
    import jupyter_client
  File "/usr/local/lib/python3.11/site-packages/jupyter_client/__init__.py", line 3, in <module>
    from .asynchronous import AsyncKernelClient
  File "/usr/local/lib/python3.11/site-packages/jupyter_client/asynchronous/__init__.py", line 1, in <module>
    from .client import AsyncKernelClient  # noqa
    ^^^^^^^^^^^^^^^^^^^^^^^^^^^^^^^^^^^^^
  File "/usr/local/lib/python3.11/site-packages/jupyter_client/asynchronous/client.py", line 5, in <module>
    import zmq.asyncio
  File "/usr/local/lib/python3.11/site-packages/zmq/asyncio.py", line 9, in <module>
    import asyncio
  File "/usr/local/Cellar/python@3.11/3.11.3/Frameworks/Python.framework/Versions/3.11/lib/python3.11/asyncio/__init__.py", line 8, in <module>
    from .base_events import *
  File "/usr/local/Cellar/python@3.11/3.11.3/Frameworks/Python.framework/Versions/3.11/lib/python3.11/asyncio/base_events.py", line 18, in <module>
    import concurrent.futures
  File "/Users/zhaoji/Develop/projects/pythonProgram/concurrent.py", line 16
    
    ^
IndentationError: expected an indented block after 'with' statement on line 15
[I 2023-05-23 17:46:20.714 ServerApp] Kernel restarted: 3f384291-a80c-4ceb-8579-731549e2b29d
Traceback (most recent call last):
  File "<frozen runpy>", line 198, in _run_module_as_main
  File "<frozen runpy>", line 88, in _run_code
  File "/usr/local/lib/python3.11/site-packages/ipykernel_launcher.py", line 15, in <module>
    from ipykernel import kernelapp as app
  File "/usr/local/lib/python3.11/site-packages/ipykernel/__init__.py", line 5, in <module>
    from .connect import *  # noqa
    ^^^^^^^^^^^^^^^^^^^^^^
  File "/usr/local/lib/python3.11/site-packages/ipykernel/connect.py", line 11, in <module>
    import jupyter_client
  File "/usr/local/lib/python3.11/site-packages/jupyter_client/__init__.py", line 3, in <module>
    from .asynchronous import AsyncKernelClient
  File "/usr/local/lib/python3.11/site-packages/jupyter_client/asynchronous/__init__.py", line 1, in <module>
    from .client import AsyncKernelClient  # noqa
    ^^^^^^^^^^^^^^^^^^^^^^^^^^^^^^^^^^^^^
  File "/usr/local/lib/python3.11/site-packages/jupyter_client/asynchronous/client.py", line 5, in <module>
    import zmq.asyncio
  File "/usr/local/lib/python3.11/site-packages/zmq/asyncio.py", line 9, in <module>
    import asyncio
  File "/usr/local/Cellar/python@3.11/3.11.3/Frameworks/Python.framework/Versions/3.11/lib/python3.11/asyncio/__init__.py", line 8, in <module>
    from .base_events import *
  File "/usr/local/Cellar/python@3.11/3.11.3/Frameworks/Python.framework/Versions/3.11/lib/python3.11/asyncio/base_events.py", line 18, in <module>
    import concurrent.futures
  File "/Users/zhaoji/Develop/projects/pythonProgram/concurrent.py", line 16
    
    ^
IndentationError: expected an indented block after 'with' statement on line 15
[I 2023-05-23 17:46:23.704 ServerApp] AsyncIOLoopKernelRestarter: restarting kernel (4/5), new random ports
Traceback (most recent call last):
  File "<frozen runpy>", line 198, in _run_module_as_main
  File "<frozen runpy>", line 88, in _run_code
  File "/usr/local/lib/python3.11/site-packages/ipykernel_launcher.py", line 15, in <module>
    from ipykernel import kernelapp as app
  File "/usr/local/lib/python3.11/site-packages/ipykernel/__init__.py", line 5, in <module>
    from .connect import *  # noqa
    ^^^^^^^^^^^^^^^^^^^^^^
  File "/usr/local/lib/python3.11/site-packages/ipykernel/connect.py", line 11, in <module>
    import jupyter_client
  File "/usr/local/lib/python3.11/site-packages/jupyter_client/__init__.py", line 3, in <module>
    from .asynchronous import AsyncKernelClient
  File "/usr/local/lib/python3.11/site-packages/jupyter_client/asynchronous/__init__.py", line 1, in <module>
    from .client import AsyncKernelClient  # noqa
    ^^^^^^^^^^^^^^^^^^^^^^^^^^^^^^^^^^^^^
  File "/usr/local/lib/python3.11/site-packages/jupyter_client/asynchronous/client.py", line 5, in <module>
    import zmq.asyncio
  File "/usr/local/lib/python3.11/site-packages/zmq/asyncio.py", line 9, in <module>
    import asyncio
  File "/usr/local/Cellar/python@3.11/3.11.3/Frameworks/Python.framework/Versions/3.11/lib/python3.11/asyncio/__init__.py", line 8, in <module>
    from .base_events import *
  File "/usr/local/Cellar/python@3.11/3.11.3/Frameworks/Python.framework/Versions/3.11/lib/python3.11/asyncio/base_events.py", line 18, in <module>
    import concurrent.futures
  File "/Users/zhaoji/Develop/projects/pythonProgram/concurrent.py", line 16
    
    ^
IndentationError: expected an indented block after 'with' statement on line 15
[I 2023-05-23 17:46:26.723 ServerApp] AsyncIOLoopKernelRestarter: restarting kernel (5/5), new random ports
Traceback (most recent call last):
  File "<frozen runpy>", line 198, in _run_module_as_main
  File "<frozen runpy>", line 88, in _run_code
  File "/usr/local/lib/python3.11/site-packages/ipykernel_launcher.py", line 15, in <module>
    from ipykernel import kernelapp as app
  File "/usr/local/lib/python3.11/site-packages/ipykernel/__init__.py", line 5, in <module>
    from .connect import *  # noqa
    ^^^^^^^^^^^^^^^^^^^^^^
  File "/usr/local/lib/python3.11/site-packages/ipykernel/connect.py", line 11, in <module>
    import jupyter_client
  File "/usr/local/lib/python3.11/site-packages/jupyter_client/__init__.py", line 3, in <module>
    from .asynchronous import AsyncKernelClient
  File "/usr/local/lib/python3.11/site-packages/jupyter_client/asynchronous/__init__.py", line 1, in <module>
    from .client import AsyncKernelClient  # noqa
    ^^^^^^^^^^^^^^^^^^^^^^^^^^^^^^^^^^^^^
  File "/usr/local/lib/python3.11/site-packages/jupyter_client/asynchronous/client.py", line 5, in <module>
    import zmq.asyncio
  File "/usr/local/lib/python3.11/site-packages/zmq/asyncio.py", line 9, in <module>
    import asyncio
  File "/usr/local/Cellar/python@3.11/3.11.3/Frameworks/Python.framework/Versions/3.11/lib/python3.11/asyncio/__init__.py", line 8, in <module>
    from .base_events import *
  File "/usr/local/Cellar/python@3.11/3.11.3/Frameworks/Python.framework/Versions/3.11/lib/python3.11/asyncio/base_events.py", line 18, in <module>
    import concurrent.futures
  File "/Users/zhaoji/Develop/projects/pythonProgram/concurrent.py", line 16
    
    ^
IndentationError: expected an indented block after 'with' statement on line 15
[W 2023-05-23 17:46:29.742 ServerApp] AsyncIOLoopKernelRestarter: restart failed
[W 2023-05-23 17:46:29.742 ServerApp] Kernel 3f384291-a80c-4ceb-8579-731549e2b29d died, removing from map.
[W 2023-05-23 17:46:29.742 ServerApp] Restarting kernel failed: 3f384291-a80c-4ceb-8579-731549e2b29d
[I 2023-05-23 17:46:35.760 ServerApp] Kernel started: a0973935-55c7-498f-bc7f-80b9651b0134
Future exception was never retrieved
future: <Future finished exception=RuntimeError('Restart failed')>
RuntimeError: Restart failed
Traceback (most recent call last):
  File "<frozen runpy>", line 198, in _run_module_as_main
  File "<frozen runpy>", line 88, in _run_code
  File "/usr/local/lib/python3.11/site-packages/ipykernel_launcher.py", line 15, in <module>
    from ipykernel import kernelapp as app
  File "/usr/local/lib/python3.11/site-packages/ipykernel/__init__.py", line 5, in <module>
    from .connect import *  # noqa
    ^^^^^^^^^^^^^^^^^^^^^^
  File "/usr/local/lib/python3.11/site-packages/ipykernel/connect.py", line 11, in <module>
    import jupyter_client
  File "/usr/local/lib/python3.11/site-packages/jupyter_client/__init__.py", line 3, in <module>
    from .asynchronous import AsyncKernelClient
  File "/usr/local/lib/python3.11/site-packages/jupyter_client/asynchronous/__init__.py", line 1, in <module>
    from .client import AsyncKernelClient  # noqa
    ^^^^^^^^^^^^^^^^^^^^^^^^^^^^^^^^^^^^^
  File "/usr/local/lib/python3.11/site-packages/jupyter_client/asynchronous/client.py", line 5, in <module>
    import zmq.asyncio
  File "/usr/local/lib/python3.11/site-packages/zmq/asyncio.py", line 9, in <module>
    import asyncio
  File "/usr/local/Cellar/python@3.11/3.11.3/Frameworks/Python.framework/Versions/3.11/lib/python3.11/asyncio/__init__.py", line 8, in <module>
    from .base_events import *
  File "/usr/local/Cellar/python@3.11/3.11.3/Frameworks/Python.framework/Versions/3.11/lib/python3.11/asyncio/base_events.py", line 18, in <module>
    import concurrent.futures
  File "/Users/zhaoji/Develop/projects/pythonProgram/concurrent.py", line 16
    
    ^
IndentationError: expected an indented block after 'with' statement on line 15
[I 2023-05-23 17:46:38.748 ServerApp] AsyncIOLoopKernelRestarter: restarting kernel (1/5), new random ports
Traceback (most recent call last):
  File "<frozen runpy>", line 198, in _run_module_as_main
  File "<frozen runpy>", line 88, in _run_code
  File "/usr/local/lib/python3.11/site-packages/ipykernel_launcher.py", line 15, in <module>
    from ipykernel import kernelapp as app
  File "/usr/local/lib/python3.11/site-packages/ipykernel/__init__.py", line 5, in <module>
    from .connect import *  # noqa
    ^^^^^^^^^^^^^^^^^^^^^^
  File "/usr/local/lib/python3.11/site-packages/ipykernel/connect.py", line 11, in <module>
    import jupyter_client
  File "/usr/local/lib/python3.11/site-packages/jupyter_client/__init__.py", line 3, in <module>
    from .asynchronous import AsyncKernelClient
  File "/usr/local/lib/python3.11/site-packages/jupyter_client/asynchronous/__init__.py", line 1, in <module>
    from .client import AsyncKernelClient  # noqa
    ^^^^^^^^^^^^^^^^^^^^^^^^^^^^^^^^^^^^^
  File "/usr/local/lib/python3.11/site-packages/jupyter_client/asynchronous/client.py", line 5, in <module>
    import zmq.asyncio
  File "/usr/local/lib/python3.11/site-packages/zmq/asyncio.py", line 9, in <module>
    import asyncio
  File "/usr/local/Cellar/python@3.11/3.11.3/Frameworks/Python.framework/Versions/3.11/lib/python3.11/asyncio/__init__.py", line 8, in <module>
    from .base_events import *
  File "/usr/local/Cellar/python@3.11/3.11.3/Frameworks/Python.framework/Versions/3.11/lib/python3.11/asyncio/base_events.py", line 18, in <module>
    import concurrent.futures
  File "/Users/zhaoji/Develop/projects/pythonProgram/concurrent.py", line 16
    
    ^
IndentationError: expected an indented block after 'with' statement on line 15
[I 2023-05-23 17:46:41.766 ServerApp] AsyncIOLoopKernelRestarter: restarting kernel (2/5), new random ports
Traceback (most recent call last):
  File "<frozen runpy>", line 198, in _run_module_as_main
  File "<frozen runpy>", line 88, in _run_code
  File "/usr/local/lib/python3.11/site-packages/ipykernel_launcher.py", line 15, in <module>
    from ipykernel import kernelapp as app
  File "/usr/local/lib/python3.11/site-packages/ipykernel/__init__.py", line 5, in <module>
    from .connect import *  # noqa
    ^^^^^^^^^^^^^^^^^^^^^^
  File "/usr/local/lib/python3.11/site-packages/ipykernel/connect.py", line 11, in <module>
    import jupyter_client
  File "/usr/local/lib/python3.11/site-packages/jupyter_client/__init__.py", line 3, in <module>
    from .asynchronous import AsyncKernelClient
  File "/usr/local/lib/python3.11/site-packages/jupyter_client/asynchronous/__init__.py", line 1, in <module>
    from .client import AsyncKernelClient  # noqa
    ^^^^^^^^^^^^^^^^^^^^^^^^^^^^^^^^^^^^^
  File "/usr/local/lib/python3.11/site-packages/jupyter_client/asynchronous/client.py", line 5, in <module>
    import zmq.asyncio
  File "/usr/local/lib/python3.11/site-packages/zmq/asyncio.py", line 9, in <module>
    import asyncio
  File "/usr/local/Cellar/python@3.11/3.11.3/Frameworks/Python.framework/Versions/3.11/lib/python3.11/asyncio/__init__.py", line 8, in <module>
    from .base_events import *
  File "/usr/local/Cellar/python@3.11/3.11.3/Frameworks/Python.framework/Versions/3.11/lib/python3.11/asyncio/base_events.py", line 18, in <module>
    import concurrent.futures
  File "/Users/zhaoji/Develop/projects/pythonProgram/concurrent.py", line 16
    
    ^
IndentationError: expected an indented block after 'with' statement on line 15
[I 2023-05-23 17:46:44.786 ServerApp] AsyncIOLoopKernelRestarter: restarting kernel (3/5), new random ports
Traceback (most recent call last):
  File "<frozen runpy>", line 198, in _run_module_as_main
  File "<frozen runpy>", line 88, in _run_code
  File "/usr/local/lib/python3.11/site-packages/ipykernel_launcher.py", line 15, in <module>
    from ipykernel import kernelapp as app
  File "/usr/local/lib/python3.11/site-packages/ipykernel/__init__.py", line 5, in <module>
    from .connect import *  # noqa
    ^^^^^^^^^^^^^^^^^^^^^^
  File "/usr/local/lib/python3.11/site-packages/ipykernel/connect.py", line 11, in <module>
    import jupyter_client
  File "/usr/local/lib/python3.11/site-packages/jupyter_client/__init__.py", line 3, in <module>
    from .asynchronous import AsyncKernelClient
  File "/usr/local/lib/python3.11/site-packages/jupyter_client/asynchronous/__init__.py", line 1, in <module>
    from .client import AsyncKernelClient  # noqa
    ^^^^^^^^^^^^^^^^^^^^^^^^^^^^^^^^^^^^^
  File "/usr/local/lib/python3.11/site-packages/jupyter_client/asynchronous/client.py", line 5, in <module>
    import zmq.asyncio
  File "/usr/local/lib/python3.11/site-packages/zmq/asyncio.py", line 9, in <module>
    import asyncio
  File "/usr/local/Cellar/python@3.11/3.11.3/Frameworks/Python.framework/Versions/3.11/lib/python3.11/asyncio/__init__.py", line 8, in <module>
    from .base_events import *
  File "/usr/local/Cellar/python@3.11/3.11.3/Frameworks/Python.framework/Versions/3.11/lib/python3.11/asyncio/base_events.py", line 18, in <module>
    import concurrent.futures
  File "/Users/zhaoji/Develop/projects/pythonProgram/concurrent.py", line 16
    
    ^
IndentationError: expected an indented block after 'with' statement on line 15
[I 2023-05-23 17:46:47.802 ServerApp] AsyncIOLoopKernelRestarter: restarting kernel (4/5), new random ports
Traceback (most recent call last):
  File "<frozen runpy>", line 198, in _run_module_as_main
  File "<frozen runpy>", line 88, in _run_code
  File "/usr/local/lib/python3.11/site-packages/ipykernel_launcher.py", line 15, in <module>
    from ipykernel import kernelapp as app
  File "/usr/local/lib/python3.11/site-packages/ipykernel/__init__.py", line 5, in <module>
    from .connect import *  # noqa
    ^^^^^^^^^^^^^^^^^^^^^^
  File "/usr/local/lib/python3.11/site-packages/ipykernel/connect.py", line 11, in <module>
    import jupyter_client
  File "/usr/local/lib/python3.11/site-packages/jupyter_client/__init__.py", line 3, in <module>
    from .asynchronous import AsyncKernelClient
  File "/usr/local/lib/python3.11/site-packages/jupyter_client/asynchronous/__init__.py", line 1, in <module>
    from .client import AsyncKernelClient  # noqa
    ^^^^^^^^^^^^^^^^^^^^^^^^^^^^^^^^^^^^^
  File "/usr/local/lib/python3.11/site-packages/jupyter_client/asynchronous/client.py", line 5, in <module>
    import zmq.asyncio
  File "/usr/local/lib/python3.11/site-packages/zmq/asyncio.py", line 9, in <module>
    import asyncio
  File "/usr/local/Cellar/python@3.11/3.11.3/Frameworks/Python.framework/Versions/3.11/lib/python3.11/asyncio/__init__.py", line 8, in <module>
    from .base_events import *
  File "/usr/local/Cellar/python@3.11/3.11.3/Frameworks/Python.framework/Versions/3.11/lib/python3.11/asyncio/base_events.py", line 18, in <module>
    import concurrent.futures
  File "/Users/zhaoji/Develop/projects/pythonProgram/concurrent.py", line 16
    
    ^
IndentationError: expected an indented block after 'with' statement on line 15
[I 2023-05-23 17:46:50.820 ServerApp] AsyncIOLoopKernelRestarter: restarting kernel (5/5), new random ports
Traceback (most recent call last):
  File "<frozen runpy>", line 198, in _run_module_as_main
  File "<frozen runpy>", line 88, in _run_code
  File "/usr/local/lib/python3.11/site-packages/ipykernel_launcher.py", line 15, in <module>
    from ipykernel import kernelapp as app
  File "/usr/local/lib/python3.11/site-packages/ipykernel/__init__.py", line 5, in <module>
    from .connect import *  # noqa
    ^^^^^^^^^^^^^^^^^^^^^^
  File "/usr/local/lib/python3.11/site-packages/ipykernel/connect.py", line 11, in <module>
    import jupyter_client
  File "/usr/local/lib/python3.11/site-packages/jupyter_client/__init__.py", line 3, in <module>
    from .asynchronous import AsyncKernelClient
  File "/usr/local/lib/python3.11/site-packages/jupyter_client/asynchronous/__init__.py", line 1, in <module>
    from .client import AsyncKernelClient  # noqa
    ^^^^^^^^^^^^^^^^^^^^^^^^^^^^^^^^^^^^^
  File "/usr/local/lib/python3.11/site-packages/jupyter_client/asynchronous/client.py", line 5, in <module>
    import zmq.asyncio
  File "/usr/local/lib/python3.11/site-packages/zmq/asyncio.py", line 9, in <module>
    import asyncio
  File "/usr/local/Cellar/python@3.11/3.11.3/Frameworks/Python.framework/Versions/3.11/lib/python3.11/asyncio/__init__.py", line 8, in <module>
    from .base_events import *
  File "/usr/local/Cellar/python@3.11/3.11.3/Frameworks/Python.framework/Versions/3.11/lib/python3.11/asyncio/base_events.py", line 18, in <module>
    import concurrent.futures
  File "/Users/zhaoji/Develop/projects/pythonProgram/concurrent.py", line 16
    
    ^
IndentationError: expected an indented block after 'with' statement on line 15
[W 2023-05-23 17:46:53.839 ServerApp] AsyncIOLoopKernelRestarter: restart failed
[W 2023-05-23 17:46:53.839 ServerApp] Kernel a0973935-55c7-498f-bc7f-80b9651b0134 died, removing from map.
[I 2023-05-23 17:46:59.517 ServerApp] Saving file at /complexData.ipynb
[I 2023-05-23 17:47:05.578 ServerApp] Kernel started: 76c037ae-872e-4742-8a02-97ca503aadcf
Traceback (most recent call last):
  File "<frozen runpy>", line 198, in _run_module_as_main
  File "<frozen runpy>", line 88, in _run_code
  File "/usr/local/lib/python3.11/site-packages/ipykernel_launcher.py", line 15, in <module>
    from ipykernel import kernelapp as app
  File "/usr/local/lib/python3.11/site-packages/ipykernel/__init__.py", line 5, in <module>
    from .connect import *  # noqa
    ^^^^^^^^^^^^^^^^^^^^^^
  File "/usr/local/lib/python3.11/site-packages/ipykernel/connect.py", line 11, in <module>
    import jupyter_client
  File "/usr/local/lib/python3.11/site-packages/jupyter_client/__init__.py", line 3, in <module>
    from .asynchronous import AsyncKernelClient
  File "/usr/local/lib/python3.11/site-packages/jupyter_client/asynchronous/__init__.py", line 1, in <module>
    from .client import AsyncKernelClient  # noqa
    ^^^^^^^^^^^^^^^^^^^^^^^^^^^^^^^^^^^^^
  File "/usr/local/lib/python3.11/site-packages/jupyter_client/asynchronous/client.py", line 5, in <module>
    import zmq.asyncio
  File "/usr/local/lib/python3.11/site-packages/zmq/asyncio.py", line 9, in <module>
    import asyncio
  File "/usr/local/Cellar/python@3.11/3.11.3/Frameworks/Python.framework/Versions/3.11/lib/python3.11/asyncio/__init__.py", line 8, in <module>
    from .base_events import *
  File "/usr/local/Cellar/python@3.11/3.11.3/Frameworks/Python.framework/Versions/3.11/lib/python3.11/asyncio/base_events.py", line 18, in <module>
    import concurrent.futures
  File "/Users/zhaoji/Develop/projects/pythonProgram/concurrent.py", line 16
    
    ^
IndentationError: expected an indented block after 'with' statement on line 15
[I 2023-05-23 17:47:08.566 ServerApp] AsyncIOLoopKernelRestarter: restarting kernel (1/5), new random ports
Traceback (most recent call last):
  File "<frozen runpy>", line 198, in _run_module_as_main
  File "<frozen runpy>", line 88, in _run_code
  File "/usr/local/lib/python3.11/site-packages/ipykernel_launcher.py", line 15, in <module>
    from ipykernel import kernelapp as app
  File "/usr/local/lib/python3.11/site-packages/ipykernel/__init__.py", line 5, in <module>
    from .connect import *  # noqa
    ^^^^^^^^^^^^^^^^^^^^^^
  File "/usr/local/lib/python3.11/site-packages/ipykernel/connect.py", line 11, in <module>
    import jupyter_client
  File "/usr/local/lib/python3.11/site-packages/jupyter_client/__init__.py", line 3, in <module>
    from .asynchronous import AsyncKernelClient
  File "/usr/local/lib/python3.11/site-packages/jupyter_client/asynchronous/__init__.py", line 1, in <module>
    from .client import AsyncKernelClient  # noqa
    ^^^^^^^^^^^^^^^^^^^^^^^^^^^^^^^^^^^^^
  File "/usr/local/lib/python3.11/site-packages/jupyter_client/asynchronous/client.py", line 5, in <module>
    import zmq.asyncio
  File "/usr/local/lib/python3.11/site-packages/zmq/asyncio.py", line 9, in <module>
    import asyncio
  File "/usr/local/Cellar/python@3.11/3.11.3/Frameworks/Python.framework/Versions/3.11/lib/python3.11/asyncio/__init__.py", line 8, in <module>
    from .base_events import *
  File "/usr/local/Cellar/python@3.11/3.11.3/Frameworks/Python.framework/Versions/3.11/lib/python3.11/asyncio/base_events.py", line 18, in <module>
    import concurrent.futures
  File "/Users/zhaoji/Develop/projects/pythonProgram/concurrent.py", line 16
    
    ^
IndentationError: expected an indented block after 'with' statement on line 15
[W 2023-05-23 17:47:10.962 ServerApp] Timeout waiting for kernel_info reply from 3f384291-a80c-4ceb-8579-731549e2b29d
[E 2023-05-23 17:47:10.963 ServerApp] Uncaught exception GET /api/kernels/3f384291-a80c-4ceb-8579-731549e2b29d/channels?session_id=d8db7f23-a97f-4899-8480-17d54695ad6d (::1)
    HTTPServerRequest(protocol='http', host='localhost:8888', method='GET', uri='/api/kernels/3f384291-a80c-4ceb-8579-731549e2b29d/channels?session_id=d8db7f23-a97f-4899-8480-17d54695ad6d', version='HTTP/1.1', remote_ip='::1')
    Traceback (most recent call last):
      File "/usr/local/lib/python3.11/site-packages/tornado/web.py", line 1786, in _execute
        result = await result
                 ^^^^^^^^^^^^
      File "/usr/local/lib/python3.11/site-packages/jupyter_server/services/kernels/websocket.py", line 67, in get
        await super().get(kernel_id=kernel_id)
      File "/usr/local/lib/python3.11/site-packages/tornado/websocket.py", line 272, in get
        await self.ws_connection.accept_connection(self)
      File "/usr/local/lib/python3.11/site-packages/tornado/websocket.py", line 862, in accept_connection
        await self._accept_connection(handler)
      File "/usr/local/lib/python3.11/site-packages/tornado/websocket.py", line 902, in _accept_connection
        self.selected_subprotocol = handler.select_subprotocol(subprotocols)
                                    ^^^^^^^^^^^^^^^^^^^^^^^^^^^^^^^^^^^^^^^^
      File "/usr/local/lib/python3.11/site-packages/jupyter_server/services/kernels/websocket.py", line 86, in select_subprotocol
        preferred_protocol = self.connection.kernel_ws_protocol
                             ^^^^^^^^^^^^^^^^^^^^^^^^^^^^^^^^^^
    AttributeError: 'NoneType' object has no attribute 'kernel_ws_protocol'
[E 2023-05-23 17:47:10.965 ServerApp] {
      "Host": "localhost:8888",
      "User-Agent": "Mozilla/5.0 (Macintosh; Intel Mac OS X 10_15_7) AppleWebKit/537.36 (KHTML, like Gecko) Chrome/113.0.0.0 Safari/537.36"
    }
[E 2023-05-23 17:47:10.965 ServerApp] 500 GET /api/kernels/3f384291-a80c-4ceb-8579-731549e2b29d/channels?session_id=d8db7f23-a97f-4899-8480-17d54695ad6d (42442f52999c44fca217868bf36576d9@::1) 60007.92ms referer=None
[I 2023-05-23 17:47:11.583 ServerApp] AsyncIOLoopKernelRestarter: restarting kernel (2/5), new random ports
Traceback (most recent call last):
  File "<frozen runpy>", line 198, in _run_module_as_main
  File "<frozen runpy>", line 88, in _run_code
  File "/usr/local/lib/python3.11/site-packages/ipykernel_launcher.py", line 15, in <module>
    from ipykernel import kernelapp as app
  File "/usr/local/lib/python3.11/site-packages/ipykernel/__init__.py", line 5, in <module>
    from .connect import *  # noqa
    ^^^^^^^^^^^^^^^^^^^^^^
  File "/usr/local/lib/python3.11/site-packages/ipykernel/connect.py", line 11, in <module>
    import jupyter_client
  File "/usr/local/lib/python3.11/site-packages/jupyter_client/__init__.py", line 3, in <module>
    from .asynchronous import AsyncKernelClient
  File "/usr/local/lib/python3.11/site-packages/jupyter_client/asynchronous/__init__.py", line 1, in <module>
    from .client import AsyncKernelClient  # noqa
    ^^^^^^^^^^^^^^^^^^^^^^^^^^^^^^^^^^^^^
  File "/usr/local/lib/python3.11/site-packages/jupyter_client/asynchronous/client.py", line 5, in <module>
    import zmq.asyncio
  File "/usr/local/lib/python3.11/site-packages/zmq/asyncio.py", line 9, in <module>
    import asyncio
  File "/usr/local/Cellar/python@3.11/3.11.3/Frameworks/Python.framework/Versions/3.11/lib/python3.11/asyncio/__init__.py", line 8, in <module>
    from .base_events import *
  File "/usr/local/Cellar/python@3.11/3.11.3/Frameworks/Python.framework/Versions/3.11/lib/python3.11/asyncio/base_events.py", line 18, in <module>
    import concurrent.futures
  File "/Users/zhaoji/Develop/projects/pythonProgram/concurrent.py", line 16
    
    ^
IndentationError: expected an indented block after 'with' statement on line 15
[I 2023-05-23 17:47:14.602 ServerApp] AsyncIOLoopKernelRestarter: restarting kernel (3/5), new random ports
Traceback (most recent call last):
  File "<frozen runpy>", line 198, in _run_module_as_main
  File "<frozen runpy>", line 88, in _run_code
  File "/usr/local/lib/python3.11/site-packages/ipykernel_launcher.py", line 15, in <module>
    from ipykernel import kernelapp as app
  File "/usr/local/lib/python3.11/site-packages/ipykernel/__init__.py", line 5, in <module>
    from .connect import *  # noqa
    ^^^^^^^^^^^^^^^^^^^^^^
  File "/usr/local/lib/python3.11/site-packages/ipykernel/connect.py", line 11, in <module>
    import jupyter_client
  File "/usr/local/lib/python3.11/site-packages/jupyter_client/__init__.py", line 3, in <module>
    from .asynchronous import AsyncKernelClient
  File "/usr/local/lib/python3.11/site-packages/jupyter_client/asynchronous/__init__.py", line 1, in <module>
    from .client import AsyncKernelClient  # noqa
    ^^^^^^^^^^^^^^^^^^^^^^^^^^^^^^^^^^^^^
  File "/usr/local/lib/python3.11/site-packages/jupyter_client/asynchronous/client.py", line 5, in <module>
    import zmq.asyncio
  File "/usr/local/lib/python3.11/site-packages/zmq/asyncio.py", line 9, in <module>
    import asyncio
  File "/usr/local/Cellar/python@3.11/3.11.3/Frameworks/Python.framework/Versions/3.11/lib/python3.11/asyncio/__init__.py", line 8, in <module>
    from .base_events import *
  File "/usr/local/Cellar/python@3.11/3.11.3/Frameworks/Python.framework/Versions/3.11/lib/python3.11/asyncio/base_events.py", line 18, in <module>
    import concurrent.futures
  File "/Users/zhaoji/Develop/projects/pythonProgram/concurrent.py", line 16
    
    ^
IndentationError: expected an indented block after 'with' statement on line 15
[I 2023-05-23 17:47:17.621 ServerApp] AsyncIOLoopKernelRestarter: restarting kernel (4/5), new random ports
Traceback (most recent call last):
  File "<frozen runpy>", line 198, in _run_module_as_main
  File "<frozen runpy>", line 88, in _run_code
  File "/usr/local/lib/python3.11/site-packages/ipykernel_launcher.py", line 15, in <module>
    from ipykernel import kernelapp as app
  File "/usr/local/lib/python3.11/site-packages/ipykernel/__init__.py", line 5, in <module>
    from .connect import *  # noqa
    ^^^^^^^^^^^^^^^^^^^^^^
  File "/usr/local/lib/python3.11/site-packages/ipykernel/connect.py", line 11, in <module>
    import jupyter_client
  File "/usr/local/lib/python3.11/site-packages/jupyter_client/__init__.py", line 3, in <module>
    from .asynchronous import AsyncKernelClient
  File "/usr/local/lib/python3.11/site-packages/jupyter_client/asynchronous/__init__.py", line 1, in <module>
    from .client import AsyncKernelClient  # noqa
    ^^^^^^^^^^^^^^^^^^^^^^^^^^^^^^^^^^^^^
  File "/usr/local/lib/python3.11/site-packages/jupyter_client/asynchronous/client.py", line 5, in <module>
    import zmq.asyncio
  File "/usr/local/lib/python3.11/site-packages/zmq/asyncio.py", line 9, in <module>
    import asyncio
  File "/usr/local/Cellar/python@3.11/3.11.3/Frameworks/Python.framework/Versions/3.11/lib/python3.11/asyncio/__init__.py", line 8, in <module>
    from .base_events import *
  File "/usr/local/Cellar/python@3.11/3.11.3/Frameworks/Python.framework/Versions/3.11/lib/python3.11/asyncio/base_events.py", line 18, in <module>
    import concurrent.futures
  File "/Users/zhaoji/Develop/projects/pythonProgram/concurrent.py", line 16
    
    ^
IndentationError: expected an indented block after 'with' statement on line 15
[I 2023-05-23 17:47:20.640 ServerApp] AsyncIOLoopKernelRestarter: restarting kernel (5/5), new random ports
[W 2023-05-23 17:47:20.740 ServerApp] Timeout waiting for kernel_info reply from 3f384291-a80c-4ceb-8579-731549e2b29d
[E 2023-05-23 17:47:20.741 ServerApp] Uncaught exception GET /api/kernels/3f384291-a80c-4ceb-8579-731549e2b29d/channels?session_id=d8db7f23-a97f-4899-8480-17d54695ad6d (::1)
    HTTPServerRequest(protocol='http', host='localhost:8888', method='GET', uri='/api/kernels/3f384291-a80c-4ceb-8579-731549e2b29d/channels?session_id=d8db7f23-a97f-4899-8480-17d54695ad6d', version='HTTP/1.1', remote_ip='::1')
    Traceback (most recent call last):
      File "/usr/local/lib/python3.11/site-packages/tornado/web.py", line 1786, in _execute
        result = await result
                 ^^^^^^^^^^^^
      File "/usr/local/lib/python3.11/site-packages/jupyter_server/services/kernels/websocket.py", line 67, in get
        await super().get(kernel_id=kernel_id)
      File "/usr/local/lib/python3.11/site-packages/tornado/websocket.py", line 272, in get
        await self.ws_connection.accept_connection(self)
      File "/usr/local/lib/python3.11/site-packages/tornado/websocket.py", line 862, in accept_connection
        await self._accept_connection(handler)
      File "/usr/local/lib/python3.11/site-packages/tornado/websocket.py", line 902, in _accept_connection
        self.selected_subprotocol = handler.select_subprotocol(subprotocols)
                                    ^^^^^^^^^^^^^^^^^^^^^^^^^^^^^^^^^^^^^^^^
      File "/usr/local/lib/python3.11/site-packages/jupyter_server/services/kernels/websocket.py", line 86, in select_subprotocol
        preferred_protocol = self.connection.kernel_ws_protocol
                             ^^^^^^^^^^^^^^^^^^^^^^^^^^^^^^^^^^
    AttributeError: 'NoneType' object has no attribute 'kernel_ws_protocol'
[E 2023-05-23 17:47:20.743 ServerApp] {
      "Host": "localhost:8888",
      "User-Agent": "Mozilla/5.0 (Macintosh; Intel Mac OS X 10_15_7) AppleWebKit/537.36 (KHTML, like Gecko) Chrome/113.0.0.0 Safari/537.36"
    }
[E 2023-05-23 17:47:20.743 ServerApp] 500 GET /api/kernels/3f384291-a80c-4ceb-8579-731549e2b29d/channels?session_id=d8db7f23-a97f-4899-8480-17d54695ad6d (42442f52999c44fca217868bf36576d9@::1) 60006.35ms referer=None
Traceback (most recent call last):
  File "<frozen runpy>", line 198, in _run_module_as_main
  File "<frozen runpy>", line 88, in _run_code
  File "/usr/local/lib/python3.11/site-packages/ipykernel_launcher.py", line 15, in <module>
    from ipykernel import kernelapp as app
  File "/usr/local/lib/python3.11/site-packages/ipykernel/__init__.py", line 5, in <module>
    from .connect import *  # noqa
    ^^^^^^^^^^^^^^^^^^^^^^
  File "/usr/local/lib/python3.11/site-packages/ipykernel/connect.py", line 11, in <module>
    import jupyter_client
  File "/usr/local/lib/python3.11/site-packages/jupyter_client/__init__.py", line 3, in <module>
    from .asynchronous import AsyncKernelClient
  File "/usr/local/lib/python3.11/site-packages/jupyter_client/asynchronous/__init__.py", line 1, in <module>
    from .client import AsyncKernelClient  # noqa
    ^^^^^^^^^^^^^^^^^^^^^^^^^^^^^^^^^^^^^
  File "/usr/local/lib/python3.11/site-packages/jupyter_client/asynchronous/client.py", line 5, in <module>
    import zmq.asyncio
  File "/usr/local/lib/python3.11/site-packages/zmq/asyncio.py", line 9, in <module>
    import asyncio
  File "/usr/local/Cellar/python@3.11/3.11.3/Frameworks/Python.framework/Versions/3.11/lib/python3.11/asyncio/__init__.py", line 8, in <module>
    from .base_events import *
  File "/usr/local/Cellar/python@3.11/3.11.3/Frameworks/Python.framework/Versions/3.11/lib/python3.11/asyncio/base_events.py", line 18, in <module>
    import concurrent.futures
  File "/Users/zhaoji/Develop/projects/pythonProgram/concurrent.py", line 16
    
    ^
IndentationError: expected an indented block after 'with' statement on line 15
[W 2023-05-23 17:47:23.657 ServerApp] AsyncIOLoopKernelRestarter: restart failed
[W 2023-05-23 17:47:23.657 ServerApp] Kernel 76c037ae-872e-4742-8a02-97ca503aadcf died, removing from map.
[W 2023-05-23 17:47:35.798 ServerApp] Timeout waiting for kernel_info reply from a0973935-55c7-498f-bc7f-80b9651b0134
[E 2023-05-23 17:47:35.799 ServerApp] Uncaught exception GET /api/kernels/a0973935-55c7-498f-bc7f-80b9651b0134/channels?session_id=de480834-94df-458d-85fe-917c7c5bfab7 (::1)
    HTTPServerRequest(protocol='http', host='localhost:8888', method='GET', uri='/api/kernels/a0973935-55c7-498f-bc7f-80b9651b0134/channels?session_id=de480834-94df-458d-85fe-917c7c5bfab7', version='HTTP/1.1', remote_ip='::1')
    Traceback (most recent call last):
      File "/usr/local/lib/python3.11/site-packages/tornado/web.py", line 1786, in _execute
        result = await result
                 ^^^^^^^^^^^^
      File "/usr/local/lib/python3.11/site-packages/jupyter_server/services/kernels/websocket.py", line 67, in get
        await super().get(kernel_id=kernel_id)
      File "/usr/local/lib/python3.11/site-packages/tornado/websocket.py", line 272, in get
        await self.ws_connection.accept_connection(self)
      File "/usr/local/lib/python3.11/site-packages/tornado/websocket.py", line 862, in accept_connection
        await self._accept_connection(handler)
      File "/usr/local/lib/python3.11/site-packages/tornado/websocket.py", line 902, in _accept_connection
        self.selected_subprotocol = handler.select_subprotocol(subprotocols)
                                    ^^^^^^^^^^^^^^^^^^^^^^^^^^^^^^^^^^^^^^^^
      File "/usr/local/lib/python3.11/site-packages/jupyter_server/services/kernels/websocket.py", line 86, in select_subprotocol
        preferred_protocol = self.connection.kernel_ws_protocol
                             ^^^^^^^^^^^^^^^^^^^^^^^^^^^^^^^^^^
    AttributeError: 'NoneType' object has no attribute 'kernel_ws_protocol'
[E 2023-05-23 17:47:35.801 ServerApp] {
      "Host": "localhost:8888",
      "User-Agent": "Mozilla/5.0 (Macintosh; Intel Mac OS X 10_15_7) AppleWebKit/537.36 (KHTML, like Gecko) Chrome/113.0.0.0 Safari/537.36"
    }
[E 2023-05-23 17:47:35.801 ServerApp] 500 GET /api/kernels/a0973935-55c7-498f-bc7f-80b9651b0134/channels?session_id=de480834-94df-458d-85fe-917c7c5bfab7 (42442f52999c44fca217868bf36576d9@::1) 60007.28ms referer=None
[W 2023-05-23 17:48:05.615 ServerApp] Timeout waiting for kernel_info reply from 76c037ae-872e-4742-8a02-97ca503aadcf
[I 2023-05-23 17:48:05.616 ServerApp] Connecting to kernel 76c037ae-872e-4742-8a02-97ca503aadcf.
[W 2023-05-23 17:48:05.619 ServerApp] 404 GET /api/kernels/76c037ae-872e-4742-8a02-97ca503aadcf/channels?session_id=4edfdf3f-1ce8-4890-86e0-96fa39412cf7 (::1): Kernel does not exist: 76c037ae-872e-4742-8a02-97ca503aadcf
[W 2023-05-23 17:48:05.630 ServerApp] 404 GET /api/kernels/76c037ae-872e-4742-8a02-97ca503aadcf/channels?session_id=4edfdf3f-1ce8-4890-86e0-96fa39412cf7 (::1): Kernel does not exist: 76c037ae-872e-4742-8a02-97ca503aadcf
[W 2023-05-23 17:48:05.631 ServerApp] 404 GET /api/kernels/76c037ae-872e-4742-8a02-97ca503aadcf/channels?session_id=4edfdf3f-1ce8-4890-86e0-96fa39412cf7 (42442f52999c44fca217868bf36576d9@::1) 1.20ms referer=None
[W 2023-05-23 17:48:05.633 ServerApp] 404 GET /api/kernels/76c037ae-872e-4742-8a02-97ca503aadcf?1684835285631 (::1): Kernel does not exist: 76c037ae-872e-4742-8a02-97ca503aadcf
[W 2023-05-23 17:48:05.633 ServerApp] wrote error: 'Kernel does not exist: 76c037ae-872e-4742-8a02-97ca503aadcf'
    Traceback (most recent call last):
      File "/usr/local/lib/python3.11/site-packages/tornado/web.py", line 1786, in _execute
        result = await result
                 ^^^^^^^^^^^^
      File "/usr/local/lib/python3.11/site-packages/jupyter_server/services/kernels/handlers.py", line 72, in get
        model = await ensure_async(km.kernel_model(kernel_id))
                                   ^^^^^^^^^^^^^^^^^^^^^^^^^^
      File "/usr/local/lib/python3.11/site-packages/jupyter_server/services/kernels/kernelmanager.py", line 496, in kernel_model
        self._check_kernel_id(kernel_id)
      File "/usr/local/lib/python3.11/site-packages/jupyter_server/services/kernels/kernelmanager.py", line 527, in _check_kernel_id
        raise web.HTTPError(404, "Kernel does not exist: %s" % kernel_id)
    tornado.web.HTTPError: HTTP 404: Not Found (Kernel does not exist: 76c037ae-872e-4742-8a02-97ca503aadcf)
[W 2023-05-23 17:48:05.634 ServerApp] 404 GET /api/kernels/76c037ae-872e-4742-8a02-97ca503aadcf?1684835285631 (42442f52999c44fca217868bf36576d9@::1) 1.34ms referer=http://localhost:8888/lab/workspaces/auto-6/tree/complexData.ipynb
[W 2023-05-23 17:48:06.947 ServerApp] 404 GET /api/kernels/76c037ae-872e-4742-8a02-97ca503aadcf/channels?session_id=4edfdf3f-1ce8-4890-86e0-96fa39412cf7 (::1): Kernel does not exist: 76c037ae-872e-4742-8a02-97ca503aadcf
[W 2023-05-23 17:48:06.948 ServerApp] 404 GET /api/kernels/76c037ae-872e-4742-8a02-97ca503aadcf/channels?session_id=4edfdf3f-1ce8-4890-86e0-96fa39412cf7 (42442f52999c44fca217868bf36576d9@::1) 1.59ms referer=None
[W 2023-05-23 17:48:06.950 ServerApp] 404 GET /api/kernels/76c037ae-872e-4742-8a02-97ca503aadcf?1684835286948 (::1): Kernel does not exist: 76c037ae-872e-4742-8a02-97ca503aadcf
[W 2023-05-23 17:48:06.951 ServerApp] wrote error: 'Kernel does not exist: 76c037ae-872e-4742-8a02-97ca503aadcf'
    Traceback (most recent call last):
      File "/usr/local/lib/python3.11/site-packages/tornado/web.py", line 1786, in _execute
        result = await result
                 ^^^^^^^^^^^^
      File "/usr/local/lib/python3.11/site-packages/jupyter_server/services/kernels/handlers.py", line 72, in get
        model = await ensure_async(km.kernel_model(kernel_id))
                                   ^^^^^^^^^^^^^^^^^^^^^^^^^^
      File "/usr/local/lib/python3.11/site-packages/jupyter_server/services/kernels/kernelmanager.py", line 496, in kernel_model
        self._check_kernel_id(kernel_id)
      File "/usr/local/lib/python3.11/site-packages/jupyter_server/services/kernels/kernelmanager.py", line 527, in _check_kernel_id
        raise web.HTTPError(404, "Kernel does not exist: %s" % kernel_id)
    tornado.web.HTTPError: HTTP 404: Not Found (Kernel does not exist: 76c037ae-872e-4742-8a02-97ca503aadcf)
[W 2023-05-23 17:48:06.951 ServerApp] 404 GET /api/kernels/76c037ae-872e-4742-8a02-97ca503aadcf?1684835286948 (42442f52999c44fca217868bf36576d9@::1) 1.27ms referer=http://localhost:8888/lab/workspaces/auto-6/tree/complexData.ipynb
[W 2023-05-23 17:48:07.906 ServerApp] 404 GET /api/kernels/76c037ae-872e-4742-8a02-97ca503aadcf/channels?session_id=4edfdf3f-1ce8-4890-86e0-96fa39412cf7 (::1): Kernel does not exist: 76c037ae-872e-4742-8a02-97ca503aadcf
[W 2023-05-23 17:48:07.907 ServerApp] 404 GET /api/kernels/76c037ae-872e-4742-8a02-97ca503aadcf/channels?session_id=4edfdf3f-1ce8-4890-86e0-96fa39412cf7 (42442f52999c44fca217868bf36576d9@::1) 1.54ms referer=None
[W 2023-05-23 17:48:07.909 ServerApp] 404 GET /api/kernels/76c037ae-872e-4742-8a02-97ca503aadcf?1684835287907 (::1): Kernel does not exist: 76c037ae-872e-4742-8a02-97ca503aadcf
[W 2023-05-23 17:48:07.910 ServerApp] wrote error: 'Kernel does not exist: 76c037ae-872e-4742-8a02-97ca503aadcf'
    Traceback (most recent call last):
      File "/usr/local/lib/python3.11/site-packages/tornado/web.py", line 1786, in _execute
        result = await result
                 ^^^^^^^^^^^^
      File "/usr/local/lib/python3.11/site-packages/jupyter_server/services/kernels/handlers.py", line 72, in get
        model = await ensure_async(km.kernel_model(kernel_id))
                                   ^^^^^^^^^^^^^^^^^^^^^^^^^^
      File "/usr/local/lib/python3.11/site-packages/jupyter_server/services/kernels/kernelmanager.py", line 496, in kernel_model
        self._check_kernel_id(kernel_id)
      File "/usr/local/lib/python3.11/site-packages/jupyter_server/services/kernels/kernelmanager.py", line 527, in _check_kernel_id
        raise web.HTTPError(404, "Kernel does not exist: %s" % kernel_id)
    tornado.web.HTTPError: HTTP 404: Not Found (Kernel does not exist: 76c037ae-872e-4742-8a02-97ca503aadcf)
[W 2023-05-23 17:48:07.910 ServerApp] 404 GET /api/kernels/76c037ae-872e-4742-8a02-97ca503aadcf?1684835287907 (42442f52999c44fca217868bf36576d9@::1) 1.23ms referer=http://localhost:8888/lab/workspaces/auto-6/tree/complexData.ipynb
[W 2023-05-23 17:48:11.013 ServerApp] 404 GET /api/kernels/76c037ae-872e-4742-8a02-97ca503aadcf/channels?session_id=4edfdf3f-1ce8-4890-86e0-96fa39412cf7 (::1): Kernel does not exist: 76c037ae-872e-4742-8a02-97ca503aadcf
[W 2023-05-23 17:48:11.014 ServerApp] 404 GET /api/kernels/76c037ae-872e-4742-8a02-97ca503aadcf/channels?session_id=4edfdf3f-1ce8-4890-86e0-96fa39412cf7 (42442f52999c44fca217868bf36576d9@::1) 1.46ms referer=None
[W 2023-05-23 17:48:11.016 ServerApp] 404 GET /api/kernels/76c037ae-872e-4742-8a02-97ca503aadcf?1684835291014 (::1): Kernel does not exist: 76c037ae-872e-4742-8a02-97ca503aadcf
[W 2023-05-23 17:48:11.017 ServerApp] wrote error: 'Kernel does not exist: 76c037ae-872e-4742-8a02-97ca503aadcf'
    Traceback (most recent call last):
      File "/usr/local/lib/python3.11/site-packages/tornado/web.py", line 1786, in _execute
        result = await result
                 ^^^^^^^^^^^^
      File "/usr/local/lib/python3.11/site-packages/jupyter_server/services/kernels/handlers.py", line 72, in get
        model = await ensure_async(km.kernel_model(kernel_id))
                                   ^^^^^^^^^^^^^^^^^^^^^^^^^^
      File "/usr/local/lib/python3.11/site-packages/jupyter_server/services/kernels/kernelmanager.py", line 496, in kernel_model
        self._check_kernel_id(kernel_id)
      File "/usr/local/lib/python3.11/site-packages/jupyter_server/services/kernels/kernelmanager.py", line 527, in _check_kernel_id
        raise web.HTTPError(404, "Kernel does not exist: %s" % kernel_id)
    tornado.web.HTTPError: HTTP 404: Not Found (Kernel does not exist: 76c037ae-872e-4742-8a02-97ca503aadcf)
[W 2023-05-23 17:48:11.017 ServerApp] 404 GET /api/kernels/76c037ae-872e-4742-8a02-97ca503aadcf?1684835291014 (42442f52999c44fca217868bf36576d9@::1) 1.20ms referer=http://localhost:8888/lab/workspaces/auto-6/tree/complexData.ipynb
[W 2023-05-23 17:48:19.144 ServerApp] 404 GET /api/kernels/76c037ae-872e-4742-8a02-97ca503aadcf/channels?session_id=4edfdf3f-1ce8-4890-86e0-96fa39412cf7 (::1): Kernel does not exist: 76c037ae-872e-4742-8a02-97ca503aadcf
[W 2023-05-23 17:48:19.145 ServerApp] 404 GET /api/kernels/76c037ae-872e-4742-8a02-97ca503aadcf/channels?session_id=4edfdf3f-1ce8-4890-86e0-96fa39412cf7 (42442f52999c44fca217868bf36576d9@::1) 1.09ms referer=None
[W 2023-05-23 17:48:19.147 ServerApp] 404 GET /api/kernels/76c037ae-872e-4742-8a02-97ca503aadcf?1684835299145 (::1): Kernel does not exist: 76c037ae-872e-4742-8a02-97ca503aadcf
[W 2023-05-23 17:48:19.147 ServerApp] wrote error: 'Kernel does not exist: 76c037ae-872e-4742-8a02-97ca503aadcf'
    Traceback (most recent call last):
      File "/usr/local/lib/python3.11/site-packages/tornado/web.py", line 1786, in _execute
        result = await result
                 ^^^^^^^^^^^^
      File "/usr/local/lib/python3.11/site-packages/jupyter_server/services/kernels/handlers.py", line 72, in get
        model = await ensure_async(km.kernel_model(kernel_id))
                                   ^^^^^^^^^^^^^^^^^^^^^^^^^^
      File "/usr/local/lib/python3.11/site-packages/jupyter_server/services/kernels/kernelmanager.py", line 496, in kernel_model
        self._check_kernel_id(kernel_id)
      File "/usr/local/lib/python3.11/site-packages/jupyter_server/services/kernels/kernelmanager.py", line 527, in _check_kernel_id
        raise web.HTTPError(404, "Kernel does not exist: %s" % kernel_id)
    tornado.web.HTTPError: HTTP 404: Not Found (Kernel does not exist: 76c037ae-872e-4742-8a02-97ca503aadcf)
[W 2023-05-23 17:48:19.148 ServerApp] 404 GET /api/kernels/76c037ae-872e-4742-8a02-97ca503aadcf?1684835299145 (42442f52999c44fca217868bf36576d9@::1) 1.18ms referer=http://localhost:8888/lab/workspaces/auto-6/tree/complexData.ipynb
[W 2023-05-23 17:48:40.475 ServerApp] 404 GET /api/kernels/76c037ae-872e-4742-8a02-97ca503aadcf/channels?session_id=4edfdf3f-1ce8-4890-86e0-96fa39412cf7 (::1): Kernel does not exist: 76c037ae-872e-4742-8a02-97ca503aadcf
[W 2023-05-23 17:48:40.475 ServerApp] 404 GET /api/kernels/76c037ae-872e-4742-8a02-97ca503aadcf/channels?session_id=4edfdf3f-1ce8-4890-86e0-96fa39412cf7 (42442f52999c44fca217868bf36576d9@::1) 1.14ms referer=None
[W 2023-05-23 17:48:40.477 ServerApp] 404 GET /api/kernels/76c037ae-872e-4742-8a02-97ca503aadcf?1684835320476 (::1): Kernel does not exist: 76c037ae-872e-4742-8a02-97ca503aadcf
[W 2023-05-23 17:48:40.478 ServerApp] wrote error: 'Kernel does not exist: 76c037ae-872e-4742-8a02-97ca503aadcf'
    Traceback (most recent call last):
      File "/usr/local/lib/python3.11/site-packages/tornado/web.py", line 1786, in _execute
        result = await result
                 ^^^^^^^^^^^^
      File "/usr/local/lib/python3.11/site-packages/jupyter_server/services/kernels/handlers.py", line 72, in get
        model = await ensure_async(km.kernel_model(kernel_id))
                                   ^^^^^^^^^^^^^^^^^^^^^^^^^^
      File "/usr/local/lib/python3.11/site-packages/jupyter_server/services/kernels/kernelmanager.py", line 496, in kernel_model
        self._check_kernel_id(kernel_id)
      File "/usr/local/lib/python3.11/site-packages/jupyter_server/services/kernels/kernelmanager.py", line 527, in _check_kernel_id
        raise web.HTTPError(404, "Kernel does not exist: %s" % kernel_id)
    tornado.web.HTTPError: HTTP 404: Not Found (Kernel does not exist: 76c037ae-872e-4742-8a02-97ca503aadcf)
[W 2023-05-23 17:48:40.478 ServerApp] 404 GET /api/kernels/76c037ae-872e-4742-8a02-97ca503aadcf?1684835320476 (42442f52999c44fca217868bf36576d9@::1) 1.22ms referer=http://localhost:8888/lab/workspaces/auto-6/tree/complexData.ipynb
[I 2023-05-23 17:49:01.517 ServerApp] Saving file at /complexData.ipynb
[W 2023-05-23 17:49:31.787 ServerApp] 404 GET /api/kernels/76c037ae-872e-4742-8a02-97ca503aadcf/channels?session_id=4edfdf3f-1ce8-4890-86e0-96fa39412cf7 (::1): Kernel does not exist: 76c037ae-872e-4742-8a02-97ca503aadcf
[W 2023-05-23 17:49:31.788 ServerApp] 404 GET /api/kernels/76c037ae-872e-4742-8a02-97ca503aadcf/channels?session_id=4edfdf3f-1ce8-4890-86e0-96fa39412cf7 (42442f52999c44fca217868bf36576d9@::1) 1.16ms referer=None
[W 2023-05-23 17:49:31.790 ServerApp] 404 GET /api/kernels/76c037ae-872e-4742-8a02-97ca503aadcf?1684835371788 (::1): Kernel does not exist: 76c037ae-872e-4742-8a02-97ca503aadcf
[W 2023-05-23 17:49:31.790 ServerApp] wrote error: 'Kernel does not exist: 76c037ae-872e-4742-8a02-97ca503aadcf'
    Traceback (most recent call last):
      File "/usr/local/lib/python3.11/site-packages/tornado/web.py", line 1786, in _execute
        result = await result
                 ^^^^^^^^^^^^
      File "/usr/local/lib/python3.11/site-packages/jupyter_server/services/kernels/handlers.py", line 72, in get
        model = await ensure_async(km.kernel_model(kernel_id))
                                   ^^^^^^^^^^^^^^^^^^^^^^^^^^
      File "/usr/local/lib/python3.11/site-packages/jupyter_server/services/kernels/kernelmanager.py", line 496, in kernel_model
        self._check_kernel_id(kernel_id)
      File "/usr/local/lib/python3.11/site-packages/jupyter_server/services/kernels/kernelmanager.py", line 527, in _check_kernel_id
        raise web.HTTPError(404, "Kernel does not exist: %s" % kernel_id)
    tornado.web.HTTPError: HTTP 404: Not Found (Kernel does not exist: 76c037ae-872e-4742-8a02-97ca503aadcf)
[W 2023-05-23 17:49:31.791 ServerApp] 404 GET /api/kernels/76c037ae-872e-4742-8a02-97ca503aadcf?1684835371788 (42442f52999c44fca217868bf36576d9@::1) 1.12ms referer=http://localhost:8888/lab/workspaces/auto-6/tree/complexData.ipynb
[I 2023-05-24 11:46:36.464 ServerApp] Creating new notebook in 
[I 2023-05-24 11:46:36.792 ServerApp] Kernel started: fdbd1da1-1bf3-4925-bc71-5d06d20db3c1
0.00s - Debugger warning: It seems that frozen modules are being used, which may
0.00s - make the debugger miss breakpoints. Please pass -Xfrozen_modules=off
0.00s - to python to disable frozen modules.
0.00s - Note: Debugging will proceed. Set PYDEVD_DISABLE_FILE_VALIDATION=1 to disable this validation.
[I 2023-05-24 11:46:37.811 ServerApp] Connecting to kernel fdbd1da1-1bf3-4925-bc71-5d06d20db3c1.
[I 2023-05-24 11:46:50.794 ServerApp] Saving file at /Untitled.ipynb
[I 2023-05-24 11:48:50.816 ServerApp] Saving file at /listAndTuple.ipynb
[I 2023-05-24 11:50:50.845 ServerApp] Saving file at /listAndTuple.ipynb
[I 2023-05-24 12:15:18.559 ServerApp] Starting buffering for fdbd1da1-1bf3-4925-bc71-5d06d20db3c1:34d29464-77ef-4cee-bbf2-838c75227e43
[I 2023-05-24 12:15:19.475 ServerApp] Creating new notebook in 
[I 2023-05-24 12:15:19.737 ServerApp] Kernel started: 407e3876-aa21-45c7-a475-1844c5ba6efb
0.00s - Debugger warning: It seems that frozen modules are being used, which may
0.00s - make the debugger miss breakpoints. Please pass -Xfrozen_modules=off
0.00s - to python to disable frozen modules.
0.00s - Note: Debugging will proceed. Set PYDEVD_DISABLE_FILE_VALIDATION=1 to disable this validation.
[I 2023-05-24 12:15:20.707 ServerApp] Connecting to kernel 407e3876-aa21-45c7-a475-1844c5ba6efb.
[I 2023-05-24 12:15:27.184 ServerApp] Saving file at /Untitled.ipynb
[I 2023-05-24 12:17:27.493 ServerApp] Saving file at /dictAndSet.ipynb
[I 2023-05-24 12:17:43.212 ServerApp] Starting buffering for 407e3876-aa21-45c7-a475-1844c5ba6efb:462d13b6-f185-4afb-83c4-614303e78aef
[I 2023-05-24 12:17:43.326 ServerApp] Connecting to kernel 407e3876-aa21-45c7-a475-1844c5ba6efb.
[I 2023-05-24 12:17:43.327 ServerApp] Restoring connection for 407e3876-aa21-45c7-a475-1844c5ba6efb:462d13b6-f185-4afb-83c4-614303e78aef
[I 2023-05-24 14:36:57.426 ServerApp] Starting buffering for 407e3876-aa21-45c7-a475-1844c5ba6efb:462d13b6-f185-4afb-83c4-614303e78aef
[I 2023-05-24 14:36:58.259 ServerApp] Creating new notebook in 
[I 2023-05-24 14:36:58.507 ServerApp] Kernel started: e98f3f23-dcbf-43d4-8599-ce902ab3630d
0.00s - Debugger warning: It seems that frozen modules are being used, which may
0.00s - make the debugger miss breakpoints. Please pass -Xfrozen_modules=off
0.00s - to python to disable frozen modules.
0.00s - Note: Debugging will proceed. Set PYDEVD_DISABLE_FILE_VALIDATION=1 to disable this validation.
[I 2023-05-24 14:36:59.488 ServerApp] Connecting to kernel e98f3f23-dcbf-43d4-8599-ce902ab3630d.
[I 2023-05-24 14:37:02.643 ServerApp] Saving file at /Untitled.ipynb
[I 2023-05-24 14:39:02.658 ServerApp] Saving file at /loop.ipynb
[I 2023-05-24 14:41:02.688 ServerApp] Saving file at /loop.ipynb
[I 2023-05-24 14:43:02.711 ServerApp] Saving file at /loop.ipynb
[I 2023-05-24 14:47:02.740 ServerApp] Saving file at /loop.ipynb
[I 2023-05-24 14:49:02.756 ServerApp] Saving file at /loop.ipynb
[I 2023-05-24 14:59:29.863 ServerApp] Saving file at /loop.ipynb
[I 2023-05-24 15:01:29.886 ServerApp] Saving file at /loop.ipynb
[I 2023-05-24 15:01:57.207 ServerApp] Saving file at /loop.ipynb
[I 2023-05-24 15:09:57.295 ServerApp] Saving file at /loop.ipynb
[I 2023-05-24 15:11:57.318 ServerApp] Saving file at /loop.ipynb
[I 2023-05-24 15:56:36.876 ServerApp] Connecting to kernel e98f3f23-dcbf-43d4-8599-ce902ab3630d.
[W 2023-05-24 16:04:07.870 ServerApp] Notebook test.ipynb is not trusted
[I 2023-05-24 16:04:08.079 ServerApp] Kernel started: cbe75d08-84b1-439e-b245-c6183baa8ec7
0.00s - Debugger warning: It seems that frozen modules are being used, which may
0.00s - make the debugger miss breakpoints. Please pass -Xfrozen_modules=off
0.00s - to python to disable frozen modules.
0.00s - Note: Debugging will proceed. Set PYDEVD_DISABLE_FILE_VALIDATION=1 to disable this validation.
[I 2023-05-24 16:04:09.083 ServerApp] Connecting to kernel cbe75d08-84b1-439e-b245-c6183baa8ec7.
[I 2023-05-24 16:06:07.946 ServerApp] Saving file at /test.ipynb
[W 2023-05-24 16:06:07.946 ServerApp] Notebook test.ipynb is not trusted
[I 2023-05-24 16:08:07.948 ServerApp] Saving file at /test.ipynb
[W 2023-05-24 16:08:07.950 ServerApp] Notebook test.ipynb is not trusted
[I 2023-05-24 16:16:29.573 ServerApp] Creating new notebook in 
[I 2023-05-24 16:16:29.857 ServerApp] Kernel started: fc263949-f61e-4ce7-94eb-2598b3357ed3
0.00s - Debugger warning: It seems that frozen modules are being used, which may
0.00s - make the debugger miss breakpoints. Please pass -Xfrozen_modules=off
0.00s - to python to disable frozen modules.
0.00s - Note: Debugging will proceed. Set PYDEVD_DISABLE_FILE_VALIDATION=1 to disable this validation.
[I 2023-05-24 16:16:30.863 ServerApp] Connecting to kernel fc263949-f61e-4ce7-94eb-2598b3357ed3.
[I 2023-05-24 16:16:35.872 ServerApp] Saving file at /Untitled.ipynb
[I 2023-05-24 16:18:35.892 ServerApp] Saving file at /abstractClassTest.ipynb
[I 2023-05-24 16:20:35.921 ServerApp] Saving file at /abstractClassTest.ipynb
